Workbook
Name BayramlarıGöster: #REF!
Name BayramlarıGöster: #REF!
Name BayramlarıGöster: #REF!
Name BayramlarıGöster: #REF!
Name BayramlarıGöster: #REF!
Name BayramlarıGöster: #REF!
Name BayramlarıGöster: #REF!
Name BayramlarıGöster: #REF!
Name BayramlarıGöster: #REF!
Name BayramlarıGöster: #REF!
Name Günler: {0,1,2,3,4,5,6} + {0;1;2;3;4;5}*7
Name Günler: {0,1,2,3,4,5,6} + {0;1;2;3;4;5}*7
Name HaftaBaşlangıcı: #REF!
Name HaftaBaşlangıcı: #REF!
Name HaftaBaşlangıcı: #REF!
Name HaftaBaşlangıcı: #REF!
Name HaftaBaşlangıcı: #REF!
Name HaftaBaşlangıcı: #REF!
Name HaftaBaşlangıcı: #REF!
Name HaftaBaşlangıcı: #REF!
Name HaftaBaşlangıcı: #REF!
Name HaftaBaşlangıcı: #REF!
Name KutlananlarıGöster: #REF!
Name KutlananlarıGöster: #REF!
Name KutlananlarıGöster: #REF!
Name KutlananlarıGöster: #REF!
Name KutlananlarıGöster: #REF!
Name KutlananlarıGöster: #REF!
Name KutlananlarıGöster: #REF!
Name KutlananlarıGöster: #REF!
Name KutlananlarıGöster: #REF!
Name KutlananlarıGöster: #REF!
Name Kutlanıyor: #REF!
Name Kutlanıyor: #REF!
Name Kutlanıyor: #REF!
Name Kutlanıyor: #REF!
Name Kutlanıyor: #REF!
Name Kutlanıyor: #REF!
Name Kutlanıyor: #REF!
Name Kutlanıyor: #REF!
Name Kutlanıyor: #REF!
Name Kutlanıyor: #REF!
Name MayısPazartesi: SUM((WEEKDAY(DATE('İG-2'!TakvimYılı,5,(ROW(INDIRECT("1:"&DAY(DATE('İG-2'!TakvimYılı,5+1,0)))))))=2)*1)
Name MayısPazartesi: SUM((WEEKDAY(DATE('İG-3'!TakvimYılı,5,(ROW(INDIRECT("1:"&DAY(DATE('İG-3'!TakvimYılı,5+1,0)))))))=2)*1)
Name MayısPazartesi: SUM((WEEKDAY(DATE('İG-4'!TakvimYılı,5,(ROW(INDIRECT("1:"&DAY(DATE('İG-4'!TakvimYılı,5+1,0)))))))=2)*1)
Name MayısPazartesi: SUM((WEEKDAY(DATE('İG-5'!TakvimYılı,5,(ROW(INDIRECT("1:"&DAY(DATE('İG-5'!TakvimYılı,5+1,0)))))))=2)*1)
Name MayısPazartesi: SUM((WEEKDAY(DATE('İG-6'!TakvimYılı,5,(ROW(INDIRECT("1:"&DAY(DATE('İG-6'!TakvimYılı,5+1,0)))))))=2)*1)
Name MayısPazartesi: SUM((WEEKDAY(DATE('İG-7'!TakvimYılı,5,(ROW(INDIRECT("1:"&DAY(DATE('İG-7'!TakvimYılı,5+1,0)))))))=2)*1)
Name MayısPazartesi: SUM((WEEKDAY(DATE('İG-8'!TakvimYılı,5,(ROW(INDIRECT("1:"&DAY(DATE('İG-8'!TakvimYılı,5+1,0)))))))=2)*1)
Name MayısPazartesi: SUM((WEEKDAY(DATE('İS-1'!TakvimYılı,5,(ROW(INDIRECT("1:"&DAY(DATE('İS-1'!TakvimYılı,5+1,0)))))))=2)*1)
Name MayısPazartesi: SUM((WEEKDAY(DATE('İşyeri ve Çalışan Bilgileri'!TakvimYılı,5,(ROW(INDIRECT("1:"&DAY(DATE('İşyeri ve Çalışan Bilgileri'!TakvimYılı,5+1,0)))))))=2)*1)
Name MayısPazartesi: SUM((WEEKDAY(DATE(TakvimYılı,5,(ROW(INDIRECT("1:"&DAY(DATE(TakvimYılı,5+1,0)))))))=2)*1)
Name TakvimYılı: #REF!
Name TakvimYılı: #REF!
Name TakvimYılı: #REF!
Name TakvimYılı: #REF!
Name TakvimYılı: #REF!
Name TakvimYılı: #REF!
Name TakvimYılı: #REF!
Name TakvimYılı: #REF!

Sheet İşyeri ve Çalışan Bilgileri
B2: İŞYERİ ve TESİS BİLGİLERİ
B4: İşyeri Adı | C4: Topkapı Liv Hospital | E4: Ticari Unvan | F4: İstinye Üniversitesi Sağlık Uygulama ver Araştırma Merkezi Topkapı Ek Bina | H4: Adres | I4: Maltepe Mahaallesi Edirne Çırpıcı yolu sokak No:9 Zeytinburnu İstanbul
B5: SGK Sicil No | C5: 2.861001e+25 | E5: NACE Kodu | F5: 86.10.13 | H5: Tel ve Faks No / E-Posta | I5: 0212 880 00 00 metin.salik@isu.edu.tr
C7: Bina Toplam Kat Sayısı | D7: Bina Yüksekliği (m)* | E7: Yapı Kat Sayısı | F7: Yapı Yüksekliği (m)* | G7: Toplam Kapalı Alan (m2) | H7: Toplam Yatak Sayısı | I7: Toplam Kapalı Alan (m2) | J7: Toplam Bahçe Alanı (m2) | K7: Toplam Kapalı Otopark Alanı (m2) | L7: Bina Yapım Yılı
B8: Genel Hastane | C8: 17 | E8: 17 | F8: 41.5 | G8: 47000 | H8: 300 | I8: 47000 | J8: 4000 | K8: 0 | L8: 2016
B9: A Blok
B10: B Blok
B11: C Blok
B12: D Blok
B13: E Blok
B14: Notlar/Açıklamalar: | C14: Tek bir bloktan oluşan hastaneler için yalnızca "Genel Hastane" satırı doldurulmalıdır. Birden çok bloktan oluşan hastaneler için toplam veriler "Genel Hastane" satırına, blok bazlı detaylar her blok için ilgili satırlara doldurulmalıdır. Tanımlar: 1) Bina Kat Sayısı ve Bina Yüksekliği: Binanın kot aldığı noktadan saçak seviyesine kadar olan katların toplamı ve bu katların toplam yüksekliğini ifade eder. 2) Yapı Kat Sayısı ve Yapı Yüksekliği: Bodrum katlar, asma katlar ve çatı arası piyesler dâhil olmak üzere, yapının inşa edilen bütün katları ve bu katların toplam yüksekliği ifade eder.
B16: ÇALIŞAN SAYILARI ve DAĞILIMI
B18: MLPCARE Çalışan Sayısı ve Dağılımı
B19: Aylar | C19: Toplam Çalışan Sayısı | D19: Toplam Çalışma Süresi (Saat) | E19: İlgili Dönemde İşe Yeni Başlayan Çalışan Sayısı | F19: Bölüm Değiştiren Çalışan Sayısı | G19: Çalışanların Cinsiyete Göre Dağılımı | I19: Özel Politika Gerektiren Çalışan Dağılımı
G20: Kadın | H20: Erkek | I20: Engelli Çalışan Sayısı | J20: Hamile Çalışan Sayısı | K20: Kronik Hastalığı Olan Çalışan Sayısı | L20: Stajyer Sayısı
B21: Ocak | C21: 222 | D21: =C21*7.5*26 -> 43290 | E21: 45 | F21: 0 | G21: 146 | H21: 76 | I21: 6 | J21: 1 | K21: 0 | L21: 0
B22: Şubat | D22: =C22*7.5*24 -> 0
B23: Mart | D23: =C23*7.5*25 -> 0
B24: Nisan | D24: =C24*7.5*24 -> 0
B25: Mayıs | D25: =C25*7.5*25 -> 0
B26: Haziran | D26: =C26*7.5*22 -> 0
B27: Temmuz | D27: =C27*7.5*26 -> 0
B28: Ağustos | D28: =C28*7.5*25 -> 0
B29: Eylül | D29: =C29*7.5*26 -> 0
B30: Ekim | D30: =C30*7.5*26 -> 0
B31: Kasım | D31: =C31*7.5*25 -> 0
B32: Aralık | D32: =C32*7.5*27 -> 0
B33: Ortalama / Toplam | C33: =IFERROR(AVERAGE(C21:C32),"0") -> 222 | D33: =SUM(D21:D32) -> 43290 | E33: =IFERROR(SUM(E21:E32),"0") -> 45 | F33: =IFERROR(SUM(F21:F32),"") -> 0 | G33: =IFERROR(AVERAGE(G21:G32),"0") -> 146 | H33: =IFERROR(AVERAGE(H21:H32),"0") -> 76 | I33: =IFERROR(AVERAGE(I21:I32),"0") -> 6 | J33: =IFERROR(AVERAGE(J21:J32),"0") -> 1 | K33: =IFERROR(AVERAGE(K21:K32),"0") -> 0 | L33: =IFERROR(AVERAGE(L21:L32),"0") -> 0
B35: Alt İşveren Çalışan Sayısı ve Dağılımı
B36: Aylar | C36: Toplam Çalışan Sayısı | D36: Toplam Çalışma Süresi (Saat) | E36: İlgili Dönemde İşe Yeni Başlayan Çalışan Sayısı | F36: Bölüm Değiştiren Çalışan Sayısı | G36: Çalışanların Cinsiyete Göre Dağılımı | I36: Özel Politika Gerektiren Çalışan Dağılımı
G37: Kadın | H37: Erkek | I37: Engelli Çalışan Sayısı | J37: Hamile Çalışan Sayısı | K37: Kronik Hastalığı Olan Çalışan Sayısı | L37: Stajyer Sayısı
B38: Ocak | C38: 91 | D38: =C38*7.5*26 -> 17745 | E38: 0 | F38: 0 | G38: 44 | H38: 47 | I38: 6 | J38: 0 | K38: 0 | L38: 0
B39: Şubat | D39: =C39*7.5*24 -> 0
B40: Mart | D40: =C40*7.5*25 -> 0
B41: Nisan | D41: =C41*7.5*24 -> 0
B42: Mayıs | D42: =C42*7.5*25 -> 0
B43: Haziran | D43: =C43*7.5*22 -> 0
B44: Temmuz | D44: =C44*7.5*26 -> 0
B45: Ağustos | D45: =C45*7.5*25 -> 0
B46: Eylül | D46: =C46*7.5*26 -> 0
...

Sheet İG-1
B2: İŞ KAZALARI, MESLEK HASTALIKLARI ve RAMAK KALA OLAY İSTATİSTİKLERİ
B4: Aylar | C4: MLPCARE İş Kazaları, Meslek Hastalıkları ve Ramak Kala Olaylar | K4: Kaza Oranları
C5: Toplam Kaza Sayısı | D5: Ciddi Kaza Sayısı | E5: Kazalardan Etkilenen Toplam Çalışan Sayısı | F5: Kayıp Gün Meydana Gelen Kaza Sayısı | G5: Kayıp Gün Meydana Gelmeyen Kaza Sayısı | H5: Kayıp Gün Sayısı | I5: Ramak Kala Olay Sayısı | J5: Meslek Hastalığı Sayısı
B6: Ocak | C6: 4 | D6: 1 | E6: 4 | F6: 1 | G6: 3 | H6: 2 | I6: 0 | J6: 0 | K6: Ciddi Kaza Oranı | L6: Kayıp Gün Oranı
B7: Şubat | K7: =IFERROR(((D18*100000)/'İşyeri ve Çalışan Bilgileri'!$C$33),"0") -> 450.45045 | L7: =IFERROR(((H18*200000)/'İşyeri ve Çalışan Bilgileri'!$D$33),"0") -> 9.2400092
B8: Mart
B9: Nisan | K9: Kaza Ağırlık Oranı | L9: Devamsızlık Oranı (%)
B10: Mayıs | K10: =IFERROR((H18/'İşyeri ve Çalışan Bilgileri'!$D$33)*100000,"0") -> 4.6200046 | L10: =IFERROR((H18/301)*100,"") -> 0.66445183
B11: Haziran
B12: Temmuz | K12: Kaza Sıklık Oranı | L12: Mesleki Hastalık Oranı
B13: Ağustos | K13: =IFERROR((C18/'İşyeri ve Çalışan Bilgileri'!$D$33)*1000000,"0") -> 92.400092 | L13: =IFERROR(J18/('İşyeri ve Çalışan Bilgileri'!D33*200000),"0") -> 0
B14: Eylül
B15: Ekim | K15: Kaza Sıklık Hızı
B16: Kasım | K16: =IFERROR((C18/'İşyeri ve Çalışan Bilgileri'!$C$33),"0") -> 0.018018018
B17: Aralık
B18: Toplam | C18: =SUM(C6:C17) -> 4 | D18: =SUM(D6:D17) -> 1 | E18: =SUM(E6:E17) -> 4 | F18: =SUM(F6:F17) -> 1 | G18: =SUM(G6:G17) -> 3 | H18: =SUM(H6:H17) -> 2 | I18: =SUM(I6:I17) -> 0 | J18: =SUM(J6:J17) -> 0
B20: Aylar | C20: MLPCARE (Yalnızca Stajyerler) İş Kazaları, Meslek Hastalıkları ve Ramak Kala Olaylar | K20: Kaza Oranları
C21: Toplam Kaza Sayısı | D21: Ciddi Kaza Sayısı | E21: Kazalardan Etkilenen Toplam Çalışan Sayısı | F21: Kayıp Gün Meydana Gelen Kaza Sayısı | G21: Kayıp Gün Meydana Gelmeyen Kaza Sayısı | H21: Kayıp Gün Sayısı | I21: Ramak Kala Olay Sayısı | J21: Meslek Hastalığı Sayısı
B22: Ocak | C22: 0 | D22: 0 | E22: 0 | F22: 0 | G22: 0 | H22: 0 | I22: 0 | J22: 0 | K22: Ciddi Kaza Oranı | L22: Kayıp Gün Oranı
B23: Şubat | K23: =IFERROR(((D34*100000)/'İşyeri ve Çalışan Bilgileri'!$C$33),"0") -> 0 | L23: =IFERROR(((H34*200000)/'İşyeri ve Çalışan Bilgileri'!$D$33),"0") -> 0
B24: Mart
B25: Nisan | K25: Kaza Ağırlık Oranı | L25: Devamsızlık Oranı (%)
B26: Mayıs | K26: =IFERROR((H34/'İşyeri ve Çalışan Bilgileri'!$D$33)*100000,"0") -> 0 | L26: =IFERROR((H34/301)*100,"") -> 0
B27: Haziran
B28: Temmuz | K28: Kaza Sıklık Oranı | L28: Mesleki Hastalık Oranı
B29: Ağustos | K29: =IFERROR((C34/'İşyeri ve Çalışan Bilgileri'!$D$33)*1000000,"0") -> 0 | L29: =IFERROR(J34/('İşyeri ve Çalışan Bilgileri'!D33*200000),"0") -> 0
B30: Eylül
B31: Ekim | K31: Kaza Sıklık Hızı
B32: Kasım | K32: =IFERROR((C34/'İşyeri ve Çalışan Bilgileri'!$C$33),"0") -> 0
B33: Aralık
B34: Toplam | C34: =SUM(C22:C33) -> 0 | D34: =SUM(D22:D33) -> 0 | E34: =SUM(E22:E33) -> 0 | F34: =SUM(F22:F33) -> 0 | G34: =SUM(G22:G33) -> 0 | H34: =SUM(H22:H33) -> 0 | I34: =SUM(I22:I33) -> 0 | J34: =SUM(J22:J33) -> 0
B36: Aylar | C36: Alt İşveren (Yemek, Temizlik, Güvenlik, Vale vb. tümü) İş Kazaları, Meslek Hastalıkları ve Ramak Kala Olaylar | K36: Kaza Oranları
C37: Toplam Kaza Sayısı | D37: Ciddi Kaza Sayısı | E37: Kazalardan Etkilenen Toplam Çalışan Sayısı | F37: Kayıp Gün Meydana Gelen Kaza Sayısı | G37: Kayıp Gün Meydana Gelmeyen Kaza Sayısı | H37: Kayıp Gün Sayısı | I37: Ramak Kala Olay Sayısı | J37: Meslek Hastalığı Sayısı
B38: Ocak | C38: 0 | D38: 0 | E38: 0 | F38: 0 | G38: 0 | H38: 0 | I38: 0 | J38: 0 | K38: Ciddi Kaza Oranı | L38: Kayıp Gün Oranı
B39: Şubat | K39: =IFERROR(((D50*100000)/'İşyeri ve Çalışan Bilgileri'!$C$50),"0") -> 0 | L39: =IFERROR(((H50*200000)/'İşyeri ve Çalışan Bilgileri'!$D$50),"0") -> 0
B40: Mart
B41: Nisan | K41: Kaza Ağırlık Oranı | L41: Devamsızlık Oranı (%)
B42: Mayıs | K42: =IFERROR((H50/'İşyeri ve Çalışan Bilgileri'!$D$50)*100000,"0") -> 0 | L42: =IFERROR((H50/301)*100,"") -> 0
B43: Haziran
B44: Temmuz | K44: Kaza Sıklık Oranı | L44: Mesleki Hastalık Oranı
...

Sheet İG-2
B2: EĞİTİM İSTATİSTİKLERİ
B4: Eğitim Adı | C4: Aylar | D4: Eğitim Alması Gereken Toplam Personel Sayısı | E4: Eğitim Alan Toplam Personel Sayısı | F4: Eğitim Tamamlama Oranı | G4: Ön Değerlendirme Başarı Puanı Ortalaması | H4: Son Değerlendirme Başarı Puanı Ortalaması | I4: Değişim | J4: Açıklamalar
B6: MLPCARE İş Sağlığı ve Güvenliği - İşe Başlama Eğitimi | C6: Ocak | D6: ='İşyeri ve Çalışan Bilgileri'!E21 -> 45 | E6: 35 | F6: =IFERROR(E6/D6,"") -> 0.77777778 | I6: =IFERROR(((H6-G6)/G6),"")
C7: Şubat | D7: ='İşyeri ve Çalışan Bilgileri'!E22 -> 0 | F7: =IFERROR(E7/D7,"") | I7: =IFERROR(((H7-G7)/G7),"")
C8: Mart | D8: ='İşyeri ve Çalışan Bilgileri'!E23 -> 0 | F8: =IFERROR(E8/D8,"") | I8: =IFERROR(((H8-G8)/G8),"")
C9: Nisan | D9: ='İşyeri ve Çalışan Bilgileri'!E24 -> 0 | F9: =IFERROR(E9/D9,"") | I9: =IFERROR(((H9-G9)/G9),"")
C10: Mayıs | D10: ='İşyeri ve Çalışan Bilgileri'!E25 -> 0 | F10: =IFERROR(E10/D10,"") | I10: =IFERROR(((H10-G10)/G10),"")
C11: Haziran | D11: ='İşyeri ve Çalışan Bilgileri'!E26 -> 0 | F11: =IFERROR(E11/D11,"") | I11: =IFERROR(((H11-G11)/G11),"")
C12: Temmuz | D12: ='İşyeri ve Çalışan Bilgileri'!E27 -> 0 | F12: =IFERROR(E12/D12,"") | I12: =IFERROR(((H12-G12)/G12),"")
C13: Ağustos | D13: ='İşyeri ve Çalışan Bilgileri'!E28 -> 0 | F13: =IFERROR(E13/D13,"") | I13: =IFERROR(((H13-G13)/G13),"")
C14: Eylül | D14: ='İşyeri ve Çalışan Bilgileri'!E29 -> 0 | F14: =IFERROR(E14/D14,"") | I14: =IFERROR(((H14-G14)/G14),"")
C15: Ekim | D15: ='İşyeri ve Çalışan Bilgileri'!E30 -> 0 | F15: =IFERROR(E15/D15,"") | I15: =IFERROR(((H15-G15)/G15),"")
C16: Kasım | D16: ='İşyeri ve Çalışan Bilgileri'!E31 -> 0 | F16: =IFERROR(E16/D16,"") | I16: =IFERROR(((H16-G16)/G16),"")
C17: Aralık | D17: ='İşyeri ve Çalışan Bilgileri'!E32 -> 0 | F17: =IFERROR(E17/D17,"") | I17: =IFERROR(((H17-G17)/G17),"")
C18: Ortalama/Toplam | D18: =SUM(D6:D17) -> 45 | E18: =SUM(E6:E17) -> 35 | F18: =IFERROR(E18/D18,0%) -> 0.77777778 | G18: =IFERROR(AVERAGE(G6:G17),0) -> 0 | H18: =IFERROR(AVERAGE(H6:H17),0) -> 0 | I18: =IFERROR(H18/G18,0%) -> 0
B19: MLPCARE Bölüm / Alan Değiştiren Personel Eğitimi | C19: Ocak | D19: ='İşyeri ve Çalışan Bilgileri'!F21 -> 0 | F19: =IFERROR(E19/D19,"") | I19: =IFERROR(((H19-G19)/G19),"")
C20: Şubat | D20: ='İşyeri ve Çalışan Bilgileri'!F22 -> 0 | F20: =IFERROR(E20/D20,"") | I20: =IFERROR(((H20-G20)/G20),"")
C21: Mart | D21: ='İşyeri ve Çalışan Bilgileri'!F23 -> 0 | F21: =IFERROR(E21/D21,"") | I21: =IFERROR(((H21-G21)/G21),"")
C22: Nisan | D22: ='İşyeri ve Çalışan Bilgileri'!F24 -> 0 | F22: =IFERROR(E22/D22,"") | I22: =IFERROR(((H22-G22)/G22),"")
C23: Mayıs | D23: ='İşyeri ve Çalışan Bilgileri'!F25 -> 0 | F23: =IFERROR(E23/D23,"") | I23: =IFERROR(((H23-G23)/G23),"")
C24: Haziran | D24: ='İşyeri ve Çalışan Bilgileri'!F26 -> 0 | F24: =IFERROR(E24/D24,"") | I24: =IFERROR(((H24-G24)/G24),"")
C25: Temmuz | D25: ='İşyeri ve Çalışan Bilgileri'!F27 -> 0 | F25: =IFERROR(E25/D25,"") | I25: =IFERROR(((H25-G25)/G25),"")
C26: Ağustos | D26: ='İşyeri ve Çalışan Bilgileri'!F28 -> 0 | F26: =IFERROR(E26/D26,"") | I26: =IFERROR(((H26-G26)/G26),"")
C27: Eylül | D27: ='İşyeri ve Çalışan Bilgileri'!F29 -> 0 | F27: =IFERROR(E27/D27,"") | I27: =IFERROR(((H27-G27)/G27),"")
C28: Ekim | D28: ='İşyeri ve Çalışan Bilgileri'!F30 -> 0 | F28: =IFERROR(E28/D28,"") | I28: =IFERROR(((H28-G28)/G28),"")
C29: Kasım | D29: ='İşyeri ve Çalışan Bilgileri'!F31 -> 0 | F29: =IFERROR(E29/D29,"") | I29: =IFERROR(((H29-G29)/G29),"")
C30: Aralık | D30: ='İşyeri ve Çalışan Bilgileri'!F32 -> 0 | F30: =IFERROR(E30/D30,"") | I30: =IFERROR(((H30-G30)/G30),"")
C31: Ortalama/Toplam | D31: =SUM(D19:D30) -> 0 | E31: =SUM(E19:E30) -> 0 | F31: =IFERROR(E31/D31,0%) -> 0 | G31: =IFERROR(AVERAGE(G19:G30),0) -> 0 | H31: =IFERROR(AVERAGE(H19:H30),0) -> 0 | I31: =IFERROR(H31/G31,0%) -> 0
B32: MLPCARE Yangın Güvenliği Eğitimi | C32: Ocak | F32: =IFERROR(E32/D32,"") | I32: =IFERROR(((H32-G32)/G32),"")
C33: Şubat | F33: =IFERROR(E33/D33,"") | I33: =IFERROR(((H33-G33)/G33),"")
C34: Mart | F34: =IFERROR(E34/D34,"") | I34: =IFERROR(((H34-G34)/G34),"")
C35: Nisan | F35: =IFERROR(E35/D35,"") | I35: =IFERROR(((H35-G35)/G35),"")
C36: Mayıs | F36: =IFERROR(E36/D36,"") | I36: =IFERROR(((H36-G36)/G36),"")
C37: Haziran | F37: =IFERROR(E37/D37,"") | I37: =IFERROR(((H37-G37)/G37),"")
C38: Temmuz | F38: =IFERROR(E38/D38,"") | I38: =IFERROR(((H38-G38)/G38),"")
C39: Ağustos | F39: =IFERROR(E39/D39,"") | I39: =IFERROR(((H39-G39)/G39),"")
C40: Eylül | F40: =IFERROR(E40/D40,"") | I40: =IFERROR(((H40-G40)/G40),"")
C41: Ekim | F41: =IFERROR(E41/D41,"") | I41: =IFERROR(((H41-G41)/G41),"")
C42: Kasım | F42: =IFERROR(E42/D42,"") | I42: =IFERROR(((H42-G42)/G42),"")
C43: Aralık | F43: =IFERROR(E43/D43,"") | I43: =IFERROR(((H43-G43)/G43),"")
...

Sheet İG-3
B2: TATBİKAT İSTATİSTİKLERİ
B4: Tatbikat Adı | C4: Tatbikat Tarihi | D4: Katılması Planlanan Toplam Kişi Sayısı | E4: Katılım Sağlayan Toplam Kişi Sayısı | F4: Katılım Oranı | G4: Tespit Edilen Uygunsuzluk Sayısı | H4: İyileştirilen Uygunsuzluk Sayısı | I4: İyileştirme Oranı | J4: Planlanan Hedef Sayısı | K4: Ulaşılan Hedef Sayısı | L4: Başarı Oranı Oranı
B6: Yangın Tatbikatı | F6: =IFERROR(E6/D6,"") | I6: =IFERROR(H6/G6,"") | L6: =IFERROR(K6/J6,"")
F7: =IFERROR(E7/D7,"") | I7: =IFERROR(H7/G7,"") | L7: =IFERROR(K7/J7,"")
F8: =IFERROR(E8/D8,"") | I8: =IFERROR(H8/G8,"") | L8: =IFERROR(K8/J8,"")
F9: =IFERROR(E9/D9,"") | I9: =IFERROR(H9/G9,"") | L9: =IFERROR(K9/J9,"")
B10: Deprem Tatbikatı | F10: =IFERROR(E10/D10,"") | I10: =IFERROR(H10/G10,"") | L10: =IFERROR(K10/J10,"")
F11: =IFERROR(E11/D11,"") | I11: =IFERROR(H11/G11,"") | L11: =IFERROR(K11/J11,"")
F12: =IFERROR(E12/D12,"") | I12: =IFERROR(H12/G12,"") | L12: =IFERROR(K12/J12,"")
F13: =IFERROR(E13/D13,"") | I13: =IFERROR(H13/G13,"") | L13: =IFERROR(K13/J13,"")
B14: Tahliye Tatbikatı | F14: =IFERROR(E14/D14,"") | I14: =IFERROR(H14/G14,"") | L14: =IFERROR(K14/J14,"")
F15: =IFERROR(E15/D15,"") | I15: =IFERROR(H15/G15,"") | L15: =IFERROR(K15/J15,"")
F16: =IFERROR(E16/D16,"") | I16: =IFERROR(H16/G16,"") | L16: =IFERROR(K16/J16,"")
F17: =IFERROR(E17/D17,"") | I17: =IFERROR(H17/G17,"") | L17: =IFERROR(K17/J17,"")
B18: Kimyasal Dökülme - Saçılma Tatbikatı | F18: =IFERROR(E18/D18,"") | I18: =IFERROR(H18/G18,"") | L18: =IFERROR(K18/J18,"")
F19: =IFERROR(E19/D19,"") | I19: =IFERROR(H19/G19,"") | L19: =IFERROR(K19/J19,"")
F20: =IFERROR(E20/D20,"") | I20: =IFERROR(H20/G20,"") | L20: =IFERROR(K20/J20,"")
F21: =IFERROR(E21/D21,"") | I21: =IFERROR(H21/G21,"") | L21: =IFERROR(K21/J21,"")
B22: HAP Tatbikatı (Masabaşı) | F22: =IFERROR(E22/D22,"") | I22: =IFERROR(H22/G22,"") | L22: =IFERROR(K22/J22,"")
F23: =IFERROR(E23/D23,"") | I23: =IFERROR(H23/G23,"") | L23: =IFERROR(K23/J23,"")
F24: =IFERROR(E24/D24,"") | I24: =IFERROR(H24/G24,"") | L24: =IFERROR(K24/J24,"")
F25: =IFERROR(E25/D25,"") | I25: =IFERROR(H25/G25,"") | L25: =IFERROR(K25/J25,"")
B26: HAP Tatbikatı (Saha) | F26: =IFERROR(E26/D26,"") | I26: =IFERROR(H26/G26,"") | L26: =IFERROR(K26/J26,"")
F27: =IFERROR(E27/D27,"") | I27: =IFERROR(H27/G27,"") | L27: =IFERROR(K27/J27,"")
F28: =IFERROR(E28/D28,"") | I28: =IFERROR(H28/G28,"") | L28: =IFERROR(K28/J28,"")
F29: =IFERROR(E29/D29,"") | I29: =IFERROR(H29/G29,"") | L29: =IFERROR(K29/J29,"")
B31: Yangın Ekipman -Sistem Tatbikatı
B33: Ekipman - Sistem Adı | D33: Tatbikat Tarihi | E33: Test Edilen Ekipman-Sistem Sayısı | F33: "Başarılı" Olan Ekipman-Sistem Sayısı | G33: Uygunluk Oranı | H33: Tespit Edilen Uygunsuzluk Sayısı | I33: İyileştirilen Uygunsuzluk Sayısı | J33: İyileştirme Oranı | K33: Açıklamalar
B35: Algılama, İhbar ve Uyarı Sistemleri | G35: =IFERROR(F35/E35,"") | J35: =IFERROR(I35/H35,"")
B36: Yangın ve Duman Yayılmasını Önleyici Sistemler | G36: =IFERROR(F36/E36,"") | J36: =IFERROR(I36/H36,"")
B37: Yangın Söndürme Sistem ve Ekipmanları | G37: =IFERROR(F37/E37,"") | J37: =IFERROR(I37/H37,"")
B38: Otomatik Yangın Söndürme Sistemleri | G38: =IFERROR(F38/E38,"") | J38: =IFERROR(I38/H38,"")
B39: Yangın Senaryosu İle İlişkili Diğer Sistemler | G39: =IFERROR(F39/E39,"") | J39: =IFERROR(I39/H39,"")

Sheet İG-4
B2: OLAĞAN DIŞI OLAY VERİLERİ
B4: Aylar | C4: Toplam Olağan Dışı Olay Sayısı | D4: Olağan Dışı Olayların Kategori Bazlı Dağılımı
D5: Yangın | E5: Patlama | F5: Sel/Su Baskını | G5: Deprem | H5: Elektrik Kesintisi | I5: Tehlikeli Madde Yayılımı | J5: Medikal Gaz Kesintisi | K5: Yapısal Unsurlara Dair Olaylar | L5: Diğer
B6: Ocak
B7: Şubat
B8: Mart
B9: Nisan
B10: Mayıs
B11: Haziran
B12: Temmuz
B13: Ağustos
B14: Eylül
B15: Ekim
B16: Kasım
B17: Aralık
B18: Toplam | C18: =SUM(C6:C17) -> 0 | D18: =SUM(D6:D17) -> 0 | E18: =SUM(E6:E17) -> 0 | F18: =SUM(F6:F17) -> 0 | G18: =SUM(G6:G17) -> 0 | H18: =SUM(H6:H17) -> 0 | I18: =SUM(I6:I17) -> 0 | J18: =SUM(J6:J17) -> 0 | ... L18: =SUM(L6:L17) -> 0
B20: OLAĞAN DIŞI OLAY DETAY BİLGİLER
B22: 2026-01 | C22: Olay Türü | G22: Olayın Gerçekleşme Şekli (Özet) | I22: Olayın Nedeni Detay | K22: Olayın Tespit Edilebilen Etkisi
C23: Olayın Kök Nedeni
C24: Olayın Gerçekleştiği Yer - Bölüm - Alan
C25: Olayın Gerçekleştiği Tarih / Saat | E25: 46026 | F25: 0
C26: Müdahale gerekti mi? Evetse müdahale saati? | E26: Hayır | F26: 0
C27: Olayın Kontrol Altına Alındığı Saat | E27: 0
C28: Destek alındı mı? Evetse kim tarafından? | E28: Evet | F28: İç Destek | G28: Olaya İlişkin Tespitler | I28: Alınan Aksiyonlar | K28: Sonuç / Değerlendirme
C29: Acil durum anonsu verildi mi? Evetse hangi kod? | E29: Evet | F29: Kırmızı Kod
C30: Hizmet kesintiye uğradı mı? Evetse kesinti süresi? | E30: Evet | F30: 1 Saat
C31: Tahliye Edilen Personel Sayısı | E31: 0
C32: Tahliye Edilen Ayaktan / Yatan Hasta Sayısı | E32: 0 | F32: 0
C33: Yaralı Sayısı / Ölü Sayısı | E33: 0 | F33: 0
B34: 2026-02 | C34: Olay Türü | G34: Olayın Gerçekleşme Şekli (Özet) | I34: Olayın Nedeni Detay | K34: Olayın Tespit Edilebilen Etkisi
C35: Olayın Kök Nedeni
C36: Olayın Gerçekleştiği Yer - Bölüm - Alan
C37: Olayın Gerçekleştiği Tarih / Saat
C38: Müdahale gerekti mi? Evetse müdahale saati?
C39: Olayın Kontrol Altına Alındığı Saat
C40: Destek alındı mı? Evetse kim tarafından? | G40: Olaya İlişkin Tespitler | I40: Alınan Aksiyonlar | K40: Sonuç / Değerlendirme
C41: Acil durum anonsu verildi mi? Evetse hangi kod?
C42: Hizmet kesintiye uğradı mı? Evetse kesinti süresi?
C43: Tahliye Edilen Personel Sayısı
C44: Tahliye Edilen Ayaktan / Yatan Hasta Sayısı
...

Sheet İG-5
B2: İŞ SAĞLIĞI VE GÜVENLİĞİ KURUL ÇALIŞMALARI VERİLERİ
B4: Aylar | C4: Olağan Toplantı Sayısı | D4: Olağanüstü Toplantı Sayısı | E4: Planlanan Toplam Katılımcı Sayısı | F4: Gerçekleşen Toplam Katılımcı Sayısı | G4: Katılım Oranı | H4: Toplantılara Katılan Alt İşveren Temsilci Sayısı | I4: Toplantılara Katılan Çalışan Temsilcisi Sayısı | J4: Planlanan Aksiyon Sayısı | K4: Tamamlanan Aksiyon Sayısı | L4: Aksiyon Tamamlama Oranı
B6: Ocak | C6: 1 | D6: 0 | E6: 13 | F6: 13 | G6: =IFERROR(F6/E6,"") -> 1 | H6: 0 | I6: 1 | J6: 6 | K6: 0 | L6: =IFERROR(K6/J6,"") -> 0
B7: Şubat | G7: =IFERROR(F7/E7,"") | L7: =IFERROR(K7/J7,"")
B8: Mart | G8: =IFERROR(F8/E8,"") | L8: =IFERROR(K8/J8,"")
B9: Nisan | G9: =IFERROR(F9/E9,"") | L9: =IFERROR(K9/J9,"")
B10: Mayıs | G10: =IFERROR(F10/E10,"") | L10: =IFERROR(K10/J10,"")
B11: Haziran | G11: =IFERROR(F11/E11,"") | L11: =IFERROR(K11/J11,"")
B12: Temmuz | G12: =IFERROR(F12/E12,"") | L12: =IFERROR(K12/J12,"")
B13: Ağustos | G13: =IFERROR(F13/E13,"") | L13: =IFERROR(K14/J13,"")
B14: Eylül | G14: =IFERROR(F14/E14,"") | L14: =IFERROR(K15/J14,"")
B15: Ekim | G15: =IFERROR(F15/E15,"") | L15: =IFERROR(K16/J15,"")
B16: Kasım | G16: =IFERROR(F16/E16,"") | L16: =IFERROR(K17/J16,"")
B17: Aralık | G17: =IFERROR(F17/E17,"") | L17: =IFERROR(K17/J17,"")
B18: Ortalama / Toplam | C18: =SUM(C6:C17) -> 1 | D18: =SUM(D6:D17) -> 0 | E18: =IFERROR(AVERAGE(E6:E17),"0") -> 13 | F18: =IFERROR(AVERAGE(F6:F17),"0") -> 13 | G18: =IFERROR(F18/E18,"0") -> 1 | H18: =IFERROR(AVERAGE(H6:H17),"0") -> 0 | I18: =IFERROR(AVERAGE(I6:I17),"0") -> 1 | J18: =SUM(J6:J17) -> 6 | K18: =SUM(K6:K17) -> 0 | L18: =IFERROR(K18/J18,"0") -> 0
B20: Aylar | C20: Kurul Kararlarının Kategori Bazlı Dağılımı
C21: Acil Durum Yönetimi | D21: Altyapı Sistemleri | E21: Cihaz-Ekipman-Malzeme Yönetimi | F21: Emniyet | G21: Güvenlik | H21: İnşaat-Renovasyon | I21: Tehlikeli Madde ve Atık Yönetimi | J21: Tıbbi Cihazlar | K21: Yangın Güvenliği | L21: Diğer
B23: Ocak | C23: =COUNTIFS($C$40:$C$749,">="&"01.01.2025",$C$40:$C$749,"<="&"31.01.2025",$F$40:$F$749,C$21) -> 0 | D23: 1 | E23: =COUNTIFS($C$40:$C$749,">="&"01.01.2025",$C$40:$C$749,"<="&"31.01.2025",$F$40:$F$749,E$21) -> 0 | F23: =COUNTIFS($C$40:$C$749,">="&"01.01.2025",$C$40:$C$749,"<="&"31.01.2025",$F$40:$F$749,F$21) -> 0 | G23: 1 | H23: =COUNTIFS($C$40:$C$749,">="&"01.01.2025",$C$40:$C$749,"<="&"31.01.2025",$F$40:$F$749,H$21) -> 0 | I23: =COUNTIFS($C$40:$C$749,">="&"01.01.2025",$C$40:$C$749,"<="&"31.01.2025",$F$40:$F$749,I$21) -> 0 | J23: =COUNTIFS($C$40:$C$749,">="&"01.01.2025",$C$40:$C$749,"<="&"31.01.2025",$F$40:$F$749,J$21) -> 0 | K23: 1 | L23: 1
B24: Şubat | C24: =COUNTIFS($C$40:$C$749,">="&"01.02.2025",$C$40:$C$749,"<="&"28.02.2025",$F$40:$F$749,C$21) -> 0 | D24: =COUNTIFS($C$40:$C$749,">="&"01.02.2025",$C$40:$C$749,"<="&"28.02.2025",$F$40:$F$749,D$21) -> 0 | E24: =COUNTIFS($C$40:$C$749,">="&"01.02.2025",$C$40:$C$749,"<="&"28.02.2025",$F$40:$F$749,E$21) -> 0 | F24: =COUNTIFS($C$40:$C$749,">="&"01.02.2025",$C$40:$C$749,"<="&"28.02.2025",$F$40:$F$749,F$21) -> 0 | G24: =COUNTIFS($C$40:$C$749,">="&"01.02.2025",$C$40:$C$749,"<="&"28.02.2025",$F$40:$F$749,G$21) -> 0 | H24: =COUNTIFS($C$40:$C$749,">="&"01.02.2025",$C$40:$C$749,"<="&"28.02.2025",$F$40:$F$749,H$21) -> 0 | I24: =COUNTIFS($C$40:$C$749,">="&"01.02.2025",$C$40:$C$749,"<="&"28.02.2025",$F$40:$F$749,I$21) -> 0 | J24: =COUNTIFS($C$40:$C$749,">="&"01.02.2025",$C$40:$C$749,"<="&"28.02.2025",$F$40:$F$749,J$21) -> 0 | ... L24: =COUNTIFS($C$40:$C$749,">="&"01.02.2025",$C$40:$C$749,"<="&"28.02.2025",$F$40:$F$749,L$21) -> 0
B25: Mart | C25: =COUNTIFS($C$40:$C$749,">="&"01.03.2025",$C$40:$C$749,"<="&"31.03.2025",$F$40:$F$749,C$21) -> 0 | D25: =COUNTIFS($C$40:$C$749,">="&"01.03.2025",$C$40:$C$749,"<="&"31.03.2025",$F$40:$F$749,D$21) -> 0 | E25: =COUNTIFS($C$40:$C$749,">="&"01.03.2025",$C$40:$C$749,"<="&"31.03.2025",$F$40:$F$749,E$21) -> 0 | F25: =COUNTIFS($C$40:$C$749,">="&"01.03.2025",$C$40:$C$749,"<="&"31.03.2025",$F$40:$F$749,F$21) -> 0 | G25: =COUNTIFS($C$40:$C$749,">="&"01.03.2025",$C$40:$C$749,"<="&"31.03.2025",$F$40:$F$749,G$21) -> 0 | H25: =COUNTIFS($C$40:$C$749,">="&"01.03.2025",$C$40:$C$749,"<="&"31.03.2025",$F$40:$F$749,H$21) -> 0 | I25: =COUNTIFS($C$40:$C$749,">="&"01.03.2025",$C$40:$C$749,"<="&"31.03.2025",$F$40:$F$749,I$21) -> 0 | J25: =COUNTIFS($C$40:$C$749,">="&"01.03.2025",$C$40:$C$749,"<="&"31.03.2025",$F$40:$F$749,J$21) -> 0 | ... L25: =COUNTIFS($C$40:$C$749,">="&"01.03.2025",$C$40:$C$749,"<="&"31.03.2025",$F$40:$F$749,L$21) -> 0
B26: Nisan | C26: =COUNTIFS($C$40:$C$749,">="&"01.04.2025",$C$40:$C$749,"<="&"30.04.2025",$F$40:$F$749,C$21) -> 0 | D26: =COUNTIFS($C$40:$C$749,">="&"01.04.2025",$C$40:$C$749,"<="&"30.04.2025",$F$40:$F$749,D$21) -> 0 | E26: =COUNTIFS($C$40:$C$749,">="&"01.04.2025",$C$40:$C$749,"<="&"30.04.2025",$F$40:$F$749,E$21) -> 0 | F26: =COUNTIFS($C$40:$C$749,">="&"01.04.2025",$C$40:$C$749,"<="&"30.04.2025",$F$40:$F$749,F$21) -> 0 | G26: =COUNTIFS($C$40:$C$749,">="&"01.04.2025",$C$40:$C$749,"<="&"30.04.2025",$F$40:$F$749,G$21) -> 0 | H26: =COUNTIFS($C$40:$C$749,">="&"01.04.2025",$C$40:$C$749,"<="&"30.04.2025",$F$40:$F$749,H$21) -> 0 | I26: =COUNTIFS($C$40:$C$749,">="&"01.04.2025",$C$40:$C$749,"<="&"30.04.2025",$F$40:$F$749,I$21) -> 0 | J26: =COUNTIFS($C$40:$C$749,">="&"01.04.2025",$C$40:$C$749,"<="&"30.04.2025",$F$40:$F$749,J$21) -> 0 | ... L26: =COUNTIFS($C$40:$C$749,">="&"01.04.2025",$C$40:$C$749,"<="&"30.04.2025",$F$40:$F$749,L$21) -> 0
B27: Mayıs | C27: =COUNTIFS($C$40:$C$749,">="&"01.05.2025",$C$40:$C$749,"<="&"31.05.2025",$F$40:$F$749,C$21) -> 0 | D27: =COUNTIFS($C$40:$C$749,">="&"01.05.2025",$C$40:$C$749,"<="&"31.05.2025",$F$40:$F$749,D$21) -> 0 | E27: =COUNTIFS($C$40:$C$749,">="&"01.05.2025",$C$40:$C$749,"<="&"31.05.2025",$F$40:$F$749,E$21) -> 0 | F27: =COUNTIFS($C$40:$C$749,">="&"01.05.2025",$C$40:$C$749,"<="&"31.05.2025",$F$40:$F$749,F$21) -> 0 | G27: =COUNTIFS($C$40:$C$749,">="&"01.05.2025",$C$40:$C$749,"<="&"31.05.2025",$F$40:$F$749,G$21) -> 0 | H27: =COUNTIFS($C$40:$C$749,">="&"01.05.2025",$C$40:$C$749,"<="&"31.05.2025",$F$40:$F$749,H$21) -> 0 | I27: =COUNTIFS($C$40:$C$749,">="&"01.05.2025",$C$40:$C$749,"<="&"31.05.2025",$F$40:$F$749,I$21) -> 0 | J27: =COUNTIFS($C$40:$C$749,">="&"01.05.2025",$C$40:$C$749,"<="&"31.05.2025",$F$40:$F$749,J$21) -> 0 | ... L27: =COUNTIFS($C$40:$C$749,">="&"01.05.2025",$C$40:$C$749,"<="&"31.05.2025",$F$40:$F$749,L$21) -> 0
B28: Haziran | C28: =COUNTIFS($C$40:$C$749,">="&"01.06.2025",$C$40:$C$749,"<="&"30.06.2025",$F$40:$F$749,C$21) -> 0 | D28: =COUNTIFS($C$40:$C$749,">="&"01.06.2025",$C$40:$C$749,"<="&"30.06.2025",$F$40:$F$749,D$21) -> 0 | E28: =COUNTIFS($C$40:$C$749,">="&"01.06.2025",$C$40:$C$749,"<="&"30.06.2025",$F$40:$F$749,E$21) -> 0 | F28: =COUNTIFS($C$40:$C$749,">="&"01.06.2025",$C$40:$C$749,"<="&"30.06.2025",$F$40:$F$749,F$21) -> 0 | G28: =COUNTIFS($C$40:$C$749,">="&"01.06.2025",$C$40:$C$749,"<="&"30.06.2025",$F$40:$F$749,G$21) -> 0 | H28: =COUNTIFS($C$40:$C$749,">="&"01.06.2025",$C$40:$C$749,"<="&"30.06.2025",$F$40:$F$749,H$21) -> 0 | I28: =COUNTIFS($C$40:$C$749,">="&"01.06.2025",$C$40:$C$749,"<="&"30.06.2025",$F$40:$F$749,I$21) -> 0 | J28: =COUNTIFS($C$40:$C$749,">="&"01.06.2025",$C$40:$C$749,"<="&"30.06.2025",$F$40:$F$749,J$21) -> 0 | ... L28: =COUNTIFS($C$40:$C$749,">="&"01.06.2025",$C$40:$C$749,"<="&"30.06.2025",$F$40:$F$749,L$21) -> 0
B29: Temmuz | C29: =COUNTIFS($C$40:$C$749,">="&"01.07.2025",$C$40:$C$749,"<="&"31.07.2025",$F$40:$F$749,C$21) -> 0 | D29: =COUNTIFS($C$40:$C$749,">="&"01.07.2025",$C$40:$C$749,"<="&"31.07.2025",$F$40:$F$749,D$21) -> 0 | E29: =COUNTIFS($C$40:$C$749,">="&"01.07.2025",$C$40:$C$749,"<="&"31.07.2025",$F$40:$F$749,E$21) -> 0 | F29: =COUNTIFS($C$40:$C$749,">="&"01.07.2025",$C$40:$C$749,"<="&"31.07.2025",$F$40:$F$749,F$21) -> 0 | G29: =COUNTIFS($C$40:$C$749,">="&"01.07.2025",$C$40:$C$749,"<="&"31.07.2025",$F$40:$F$749,G$21) -> 0 | H29: =COUNTIFS($C$40:$C$749,">="&"01.07.2025",$C$40:$C$749,"<="&"31.07.2025",$F$40:$F$749,H$21) -> 0 | I29: =COUNTIFS($C$40:$C$749,">="&"01.07.2025",$C$40:$C$749,"<="&"31.07.2025",$F$40:$F$749,I$21) -> 0 | J29: =COUNTIFS($C$40:$C$749,">="&"01.07.2025",$C$40:$C$749,"<="&"31.07.2025",$F$40:$F$749,J$21) -> 0 | ... L29: =COUNTIFS($C$40:$C$749,">="&"01.07.2025",$C$40:$C$749,"<="&"31.07.2025",$F$40:$F$749,L$21) -> 0
B30: Ağustos | C30: =COUNTIFS($C$40:$C$749,">="&"01.08.2025",$C$40:$C$749,"<="&"31.08.2025",$F$40:$F$749,C$21) -> 0 | D30: =COUNTIFS($C$40:$C$749,">="&"01.08.2025",$C$40:$C$749,"<="&"31.08.2025",$F$40:$F$749,D$21) -> 0 | E30: =COUNTIFS($C$40:$C$749,">="&"01.08.2025",$C$40:$C$749,"<="&"31.08.2025",$F$40:$F$749,E$21) -> 0 | F30: =COUNTIFS($C$40:$C$749,">="&"01.08.2025",$C$40:$C$749,"<="&"31.08.2025",$F$40:$F$749,F$21) -> 0 | G30: =COUNTIFS($C$40:$C$749,">="&"01.08.2025",$C$40:$C$749,"<="&"31.08.2025",$F$40:$F$749,G$21) -> 0 | H30: =COUNTIFS($C$40:$C$749,">="&"01.08.2025",$C$40:$C$749,"<="&"31.08.2025",$F$40:$F$749,H$21) -> 0 | I30: =COUNTIFS($C$40:$C$749,">="&"01.08.2025",$C$40:$C$749,"<="&"31.08.2025",$F$40:$F$749,I$21) -> 0 | J30: =COUNTIFS($C$40:$C$749,">="&"01.08.2025",$C$40:$C$749,"<="&"31.08.2025",$F$40:$F$749,J$21) -> 0 | ... L30: =COUNTIFS($C$40:$C$749,">="&"01.08.2025",$C$40:$C$749,"<="&"31.08.2025",$F$40:$F$749,L$21) -> 0
B31: Eylül | C31: =COUNTIFS($C$40:$C$749,">="&"01.09.2025",$C$40:$C$749,"<="&"30.09.2025",$F$40:$F$749,C$21) -> 0 | D31: =COUNTIFS($C$40:$C$749,">="&"01.09.2025",$C$40:$C$749,"<="&"30.09.2025",$F$40:$F$749,D$21) -> 0 | E31: =COUNTIFS($C$40:$C$749,">="&"01.09.2025",$C$40:$C$749,"<="&"30.09.2025",$F$40:$F$749,E$21) -> 0 | F31: =COUNTIFS($C$40:$C$749,">="&"01.09.2025",$C$40:$C$749,"<="&"30.09.2025",$F$40:$F$749,F$21) -> 0 | G31: =COUNTIFS($C$40:$C$749,">="&"01.09.2025",$C$40:$C$749,"<="&"30.09.2025",$F$40:$F$749,G$21) -> 0 | H31: =COUNTIFS($C$40:$C$749,">="&"01.09.2025",$C$40:$C$749,"<="&"30.09.2025",$F$40:$F$749,H$21) -> 0 | I31: =COUNTIFS($C$40:$C$749,">="&"01.09.2025",$C$40:$C$749,"<="&"30.09.2025",$F$40:$F$749,I$21) -> 0 | J31: =COUNTIFS($C$40:$C$749,">="&"01.09.2025",$C$40:$C$749,"<="&"30.09.2025",$F$40:$F$749,J$21) -> 0 | ... L31: =COUNTIFS($C$40:$C$749,">="&"01.09.2025",$C$40:$C$749,"<="&"30.09.2025",$F$40:$F$749,L$21) -> 0
B32: Ekim | C32: =COUNTIFS($C$40:$C$749,">="&"01.10.2025",$C$40:$C$749,"<="&"31.10.2025",$F$40:$F$749,C$21) -> 0 | D32: =COUNTIFS($C$40:$C$749,">="&"01.10.2025",$C$40:$C$749,"<="&"31.10.2025",$F$40:$F$749,D$21) -> 0 | E32: =COUNTIFS($C$40:$C$749,">="&"01.10.2025",$C$40:$C$749,"<="&"31.10.2025",$F$40:$F$749,E$21) -> 0 | F32: =COUNTIFS($C$40:$C$749,">="&"01.10.2025",$C$40:$C$749,"<="&"31.10.2025",$F$40:$F$749,F$21) -> 0 | G32: =COUNTIFS($C$40:$C$749,">="&"01.10.2025",$C$40:$C$749,"<="&"31.10.2025",$F$40:$F$749,G$21) -> 0 | H32: =COUNTIFS($C$40:$C$749,">="&"01.10.2025",$C$40:$C$749,"<="&"31.10.2025",$F$40:$F$749,H$21) -> 0 | I32: =COUNTIFS($C$40:$C$749,">="&"01.10.2025",$C$40:$C$749,"<="&"31.10.2025",$F$40:$F$749,I$21) -> 0 | J32: =COUNTIFS($C$40:$C$749,">="&"01.10.2025",$C$40:$C$749,"<="&"31.10.2025",$F$40:$F$749,J$21) -> 0 | ... L32: =COUNTIFS($C$40:$C$749,">="&"01.10.2025",$C$40:$C$749,"<="&"31.10.2025",$F$40:$F$749,L$21) -> 0
B33: Kasım | C33: =COUNTIFS($C$40:$C$749,">="&"01.11.2025",$C$40:$C$749,"<="&"30.11.2025",$F$40:$F$749,C$21) -> 0 | D33: =COUNTIFS($C$40:$C$749,">="&"01.11.2025",$C$40:$C$749,"<="&"30.11.2025",$F$40:$F$749,D$21) -> 0 | E33: =COUNTIFS($C$40:$C$749,">="&"01.11.2025",$C$40:$C$749,"<="&"30.11.2025",$F$40:$F$749,E$21) -> 0 | F33: =COUNTIFS($C$40:$C$749,">="&"01.11.2025",$C$40:$C$749,"<="&"30.11.2025",$F$40:$F$749,F$21) -> 0 | G33: =COUNTIFS($C$40:$C$749,">="&"01.11.2025",$C$40:$C$749,"<="&"30.11.2025",$F$40:$F$749,G$21) -> 0 | H33: =COUNTIFS($C$40:$C$749,">="&"01.11.2025",$C$40:$C$749,"<="&"30.11.2025",$F$40:$F$749,H$21) -> 0 | I33: =COUNTIFS($C$40:$C$749,">="&"01.11.2025",$C$40:$C$749,"<="&"30.11.2025",$F$40:$F$749,I$21) -> 0 | J33: =COUNTIFS($C$40:$C$749,">="&"01.11.2025",$C$40:$C$749,"<="&"30.11.2025",$F$40:$F$749,J$21) -> 0 | ... L33: =COUNTIFS($C$40:$C$749,">="&"01.11.2025",$C$40:$C$749,"<="&"30.11.2025",$F$40:$F$749,L$21) -> 0
B34: Aralık | C34: =COUNTIFS($C$40:$C$749,">="&"01.12.2025",$C$40:$C$749,"<="&"31.12.2025",$F$40:$F$749,C$21) -> 0 | D34: =COUNTIFS($C$40:$C$749,">="&"01.12.2025",$C$40:$C$749,"<="&"31.12.2025",$F$40:$F$749,D$21) -> 0 | E34: =COUNTIFS($C$40:$C$749,">="&"01.12.2025",$C$40:$C$749,"<="&"31.12.2025",$F$40:$F$749,E$21) -> 0 | F34: =COUNTIFS($C$40:$C$749,">="&"01.12.2025",$C$40:$C$749,"<="&"31.12.2025",$F$40:$F$749,F$21) -> 0 | G34: =COUNTIFS($C$40:$C$749,">="&"01.12.2025",$C$40:$C$749,"<="&"31.12.2025",$F$40:$F$749,G$21) -> 0 | H34: =COUNTIFS($C$40:$C$749,">="&"01.12.2025",$C$40:$C$749,"<="&"31.12.2025",$F$40:$F$749,H$21) -> 0 | I34: =COUNTIFS($C$40:$C$749,">="&"01.12.2025",$C$40:$C$749,"<="&"31.12.2025",$F$40:$F$749,I$21) -> 0 | J34: =COUNTIFS($C$40:$C$749,">="&"01.12.2025",$C$40:$C$749,"<="&"31.12.2025",$F$40:$F$749,J$21) -> 0 | ... L34: =COUNTIFS($C$40:$C$749,">="&"01.12.2025",$C$40:$C$749,"<="&"31.12.2025",$F$40:$F$749,L$21) -> 0
B35: Toplam | C35: =SUM(C23:C34) -> 0 | D35: =SUM(D23:D34) -> 1 | E35: =SUM(E23:E34) -> 0 | F35: =SUM(F23:F34) -> 0 | G35: =SUM(G23:G34) -> 1 | H35: =SUM(H23:H34) -> 0 | I35: =SUM(I23:I34) -> 0 | J35: =SUM(J23:J34) -> 0 | ... L35: =SUM(L23:L34) -> 1
B37: İŞ SAĞLIĞI VE GÜVENLİĞİ KURUL TOPLANTI KARARLARI
B39: Toplantı No | C39: Toplantı Tarihi | D39: Alınan Kararlar | F39: İlgili Kategori | G39: Sorumlu | H39: Mevcut Durum | I39: Termin | J39: Tamamlanma Tarihi | K39: Sonuç / Açıklama / Değerlendirme
B40: 2026-01 | C40: 46050 | D40: Oluşturulan Acil Durum Ekiplerinin ilgili yerlerden (İtfaiye ve İlkyardım eğitim merkezi) eğitim alması için planlanma yapılmasına karar verilmiştir. | F40: Acil Durum Yönetimi | G40: İnsan Kaynakları Müdürlüğü | H40: Devam Ediyor | I40: 46081 | K40: Ekip sayıları belirlenmiştir. Yedekleri ile birlikte belirlenip ona göre itfaiye ve ilgili kurumlardan eğitim için randevu ve planlama yapılacaktır.
B41: 2026-01 | C41: 46050 | D41: Tıbbi Atık, Tehlikeli Atık alanlarında soğuk hava depoları ve konteyner içinde acil durum butonu ve ikaz sireni takılı değildir. Bu alanların uygun şekilde acil durum butonu ve ikaz sireni takılmasına karar verilmiştir. | F41: Güvenlik | G41: Teknik Hizmetleri Müdürlüğü İdari ve Destek Hizmetler Müdürlüğü | H41: Başlamadı | I41: 46081 | K41: Tıbbi atık ve tehlikeli atık alanlarında acil durum butonu ve ikaz sireni takılı değildir.
B42: 2026-01 | C42: 46050 | D42: Laboratuvar alanında yer alan Göz duşu ve duş alanı takılı ama altyapı olarak gerekli düzenleme yapılmamıştır. | F42: İnşaat-Renovasyon | G42: Teknik Hizmetler Müdürlüğü | H42: Başlamadı | I42: 46081 | K42: Göz duşu ve duş alanı takılmıştır ama gider hattı çalışması için altyapı çalışması yapılması gerekmektedir.
B43: 2026-01 | C43: 46050 | D43: KBRN ünitesi Acil girişi için düzenlenmiştir, fakat ilgili alanda duş başlıkları ve gider hattı gibi altyapı çalışması tamamlanmıştır. İlgili alan aktif hale getirilmesi için karar verilmiştir. | F43: İnşaat-Renovasyon | G43: Teknik Hizmetler Müdürlüğü | H43: Başlamadı | I43: 46081 | K43: KBRN ünitesinde eksiklikler İnşaat firması ile görüşülerek tamamlanması sağlanmalıdır.
B44: 2026-01 | C44: 46050 | D44: Personeller için Sigara içme alanın belirlenmesine karar verilmiştir. Belirtilen yerler ( Personel giriş alanı yanı ve çardak bölümü) için yerinde tespit yapılarak karar verilmesi uygun bulunmuştur. | F44: Diğer | G44: Genel Müd. Yrd. Teknik Hizmetler Müdürlüğü | H44: Devam Ediyor | I44: 46081 | K44: İlgili alanlar gezilmiş ve karar için üst yönetimin onayı beklenmektedir.
B45: 2026-01 | C45: 46050 | D45: 11.12.2025 tarihinde yapılmış olan Yangın denetimi raporu değerlendirilmiş olup. Bununla ilgili olarak ayrı bir rapor hazırlanmasına karar verilmiştir. Bu raporda ilgili tüm eksiklikler o rapor için tek tek takip edilecektir. | F45: Yangın Güvenliği | G45: Teknik Hizmetler Müdürlüğü Üst Yönetim | H45: Başlamadı | I45: 46112 | K45: Denetim sonucunda tespit edilen tüm eksikliklerle ilgili olarak aksiyon planları hazırlanıp süreçlerle ilgili bilgilendirme alınacaktır.

Sheet İG-6
B2: PERİYODİK KONTROLLER
B4: Elektrik Sistemleri | D4: 1. Kontrol | H4: 2. Kontrol | L4: Açıklamalar
D5: Kontrol Tarihi | E5: Ekipman /Tesisat Sayısı | F5: Uygunsuzluk Sayısı | G5: Not | H5: Kontrol Tarihi | I5: Ekipman /Tesisat Sayısı | J5: Uygunsuzluk Sayısı | K5: Not
B6: Elektrik İç Tesisat Kontrolü
B7: Topraklama Kontrolü
B8: Artık-Kaçak Akım Kontrolü
B9: Elektrik Panosu Görsel ve Fonks. Testleri
B10: Termografik Muayene
B11: Jeneratör Kontrolü
B12: UPS Kontrolü
B14: Mekanik Sistemler | D14: 1. Kontrol | H14: 2. Kontrol | L14: Açıklamalar
D15: Kontrol Tarihi | E15: Ekipman /Tesisat Sayısı | F15: Uygunsuzluk Sayısı | G15: Not | H15: Kontrol Tarihi | I15: Ekipman /Tesisat Sayısı | J15: Uygunsuzluk Sayısı | K15: Not
B16: Asansörler
B17: Atık Su Tesisatı
B18: Boyler
B19: Endüstriyel Kapılar
B20: Endüstriyel Raflar
B21: Forkliftler
B22: Genleşme Tankları
B23: Hava Tankları ve Kompresörler
B24: Havalandırma Tesisatı
B25: Hidrofor
B26: Likit Oksijen Tankı
B27: Otoklavlar
... B32: Yürüyen Merdivenler
B34: Yangın Algılama ve Uyarı Sistemi Kontrolü | D34: 1. Kontrol | H34: 2. Kontrol | L34: Açıklamalar
D35: Kontrol Tarihi | E35: Ekipman /Tesisat Sayısı | F35: Uygunsuzluk Sayısı | G35: Not | H35: Kontrol Tarihi | I35: Ekipman /Tesisat Sayısı | J35: Uygunsuzluk Sayısı | K35: Not
B36: Yangın Paneli
B37: Alarm Butonları
B38: Flaşörler
B39: Sirenler
B40: Duman Dedektörleri
B41: Isı Dedektörleri
B42: Multi Dedektörler
B44: Sulu Söndürme Sistemleri Kontrolü | D44: 1. Kontrol | H44: 2. Kontrol | L44: Açıklamalar
D45: Kontrol Tarihi | E45: Ekipman /Tesisat Sayısı | F45: Uygunsuzluk Sayısı | G45: Not | H45: Kontrol Tarihi | I45: Ekipman /Tesisat Sayısı | J45: Uygunsuzluk Sayısı | K45: Not
B46: Yangın Pompaları
B47: Yangın Hattı Boru Tesisatı
B48: Yangın Hortum Dolapları
B49: Yağmurlama Sistemi
...

Sheet İG-7
B2: İŞ HİJYENİ ÖLÇÜMLERİ
B4: Ölçüm Türü | D4: 1.Ölçüm Tarihi | E4: Nokta / Kişi Sayısı | F4: Uygunsuzluk Sayısı | G4: 2.Ölçüm Tarihi | H4: Nokta / Kişi Sayısı | I4: Uygunsuzluk Sayısı | J4: 3.Ölçüm Tarihi | K4: Nokta / Kişi Sayısı | L4: Uygunsuzluk Sayısı
B6: Termal Konfor Ölçümü
B7: Aydınlatma Ölçümü
B8: Gürültü Ölçümü (Ortam)
B9: Gürültü Ölçümü (Kişisel Maruziyet)
B10: Titreşim Ölçümü (Kişisel Maruziyet)
B11: Toz Ölçümü
B12: Uçucu Organik Madde Ölçümü (Ortam)
B13: Uçucu Organik Madde Ölçümü (Kişisel Maruziyet)
B14: Kimyasal Madde Ölçümü (Ortam)
B16: TERMAL KONFOR ÖLÇÜMLERİ | G16: GÜRÜLTÜ ÖLÇÜMÜ (ORTAM) | J16: GÜRÜLTÜ ÖLÇÜMÜ (KİŞİSEL MARUZİYET)
B17: Ölçüm Yapılan Noktalar | D17: Ölçüm Sonuçları | G17: Ölçüm Yapılan Noktalar | I17: Ölçüm Sonuçları | J17: Ölçüm Yapılan Kişiler (Sicil No/Ad Soyad) | K17: Ölçüm Yapılan Yer | L17: Ölçüm Sonuçları
D18: Sıcaklık ( oC ) | E18: Nem (%) | F18: Hava Akım Hızı (m/sn) | I18: Leq (dBA) | L18: Leq (dBA)
G19: Yenidoğan Yoğun Bakım*
B69: Sınır Değerler Sıcaklık: 15-30 oC Nem:30-60 % Hava Akım Hızı: 0,1-0,5 m/sn | G69: En düşük maruziyet eylem değerleri: 80 dB(A) En yüksek maruziyet eylem değerleri: 85 dB(A) Maruziyet sınır değerleri: 87 dB(A) | J69: *Yenidoğan Yoğun Bakım Gürültü Düzeyi için aşağıdaki değerler referans alınmalıdır. Tavsiye edilen gürültü düzeyi: 45 dB(A) veya daha düşük. Kabul edilebilir gürültü düzeyi: 45 - 55 dB(A) Gürültü düzeyi üst sınırı: 55 db(A)
B71: TİTREŞİM ÖLÇÜMÜ (KİŞİSEL MARUZİYET) | E71: KİMYASAL MADDE VE UÇUCU ORGANİK MADDE ÖLÇÜMÜ (ORTAM) | I71: KİMYASAL MADDE VE UÇUCU ORGANİK MADDE ÖLÇÜMÜ (KİŞİSEL MARUZİYET)
B72: Ölçüm Yapılan Kişiler (Sicil No/Ad Soyad) | C72: Ölçüm Yapılan Yer | D72: Ölçüm Sonuçları | E72: Ölçüm Yapılan Noktalar | G72: Ölçüm Türü | H72: Ölçüm Sonuçları | I72: Ölçüm Yapılan Kişiler (Sicil No/Ad Soyad) | J72: Ölçüm Yapılan Yer | K72: Ölçüm Türü | L72: Ölçüm Sonuçları
D73: Titreşim (m/s2) | H73: mg\m3 | L73: mg\m3
B97: Bütün vücut: Maruziyet sınır değeri: 1,15 m/s2, Maruziyet eylem değeri: 0,5 m/s2 El-kol titreşimi: Maruziyet sınır değeri: 5 m/s2, Maruziyet eylem değeri: 2,5 m/s2
B100: AYDINLATMA ÖLÇÜMLERİ (ORTAM) | J100: TOZ ÖLÇÜMÜ (ORTAM)
B101: Ölçüm Yapılan Noktalar | D101: Ölçüm Sonuçları (lux) | J101: Ölçüm Yapılan Noktalar | L101: Ölçüm Sonuçları
D102: 50 Lux'e Göre | E102: 100 Lux'e Göre | F102: 200 Lux'e Göre | G102: 300 Lux'e Göre | H102: 500 Lux'e Göre | I102: 1000 Lux'e Göre | L102: mg\m3

Sheet İG-8
B2: ONAYLI DEFTER
B4: Tarih | C4: Tespit / Öneri | J4: Tespit / Önerinin Kim Tarafından Yapıldığı | K4: Sonuç / Açıklama / Değerlendirme

Sheet İS-1
B2: İŞ SAĞLIĞI İSTATİSTİKLERİ
B4: MLPCARE Çalışanları İşe Giriş ve Periyodik Muayene
B5: Aylar | C5: İşe Giriş Muayenesi | H5: Periyodik Kontrol
C6: İlgili Dönemde İşe Giriş Yapan Çalışan Sayısı | D6: Önceki Dönemden Devreden İşe Giriş Muayenesi Gereken Çalışan Sayısı | E6: İlgili Dönemde İşe Giriş Muayenesi Gereken Toplam Çalışan Sayısı | F6: İşe Giriş Muayenesi Yapılan Çalışan Sayısı | G6: İşe Giriş Muayenesi Tamamlama Oranı | H6: İlgili Dönemde Periyodik Muayene Gereken Çalışan Sayısı | I6: Önceki Dönemden Devreden Periyodik Muayene Gereken Çalışan Sayısı | J6: İlgili Dönemde Periyodik Muayene Gereken Toplam Çalışan Sayısı | K6: Periyodik Muayenesi Yapılan Çalışan Sayısı | L6: Periyodik Muayene Tamamlama Oranı
B9: Ocak | C9: ='İşyeri ve Çalışan Bilgileri'!E21 -> 45 | D9: 0 | E9: =IF(ISBLANK(C9)=TRUE," ",SUM(C9,D9)) -> 45 | G9: =IFERROR(F9/E9,"-") -> 0 | I9: 0 | J9: =IF(ISBLANK(H9)=TRUE," ",SUM(H9,I9)) | L9: =IFERROR(K9/J9,"-") -> -
B10: Şubat | C10: ='İşyeri ve Çalışan Bilgileri'!E22 -> 0 | D10: =IF(OR(ISBLANK(C9)=TRUE,ISBLANK(F9)=TRUE,ISBLANK(E9)=TRUE)," ",E9-F9) | E10: =IF(ISBLANK(C10)=TRUE," ",SUM(C10,D10)) -> 0 | G10: =IFERROR(F10/E10,"-") -> - | I10: =IF(OR(ISBLANK(H9)=TRUE,ISBLANK(K9)=TRUE,ISBLANK(J9)=TRUE)," ",J9-K9) | J10: =IF(ISBLANK(H10)=TRUE," ",SUM(H10,I10)) | L10: =IFERROR(K10/J10,"-") -> -
B11: Mart | C11: ='İşyeri ve Çalışan Bilgileri'!E23 -> 0 | D11: =IF(OR(ISBLANK(C10)=TRUE,ISBLANK(F10)=TRUE,ISBLANK(E10)=TRUE)," ",E10-F10) | E11: =IF(ISBLANK(C11)=TRUE," ",SUM(C11,D11)) -> 0 | G11: =IFERROR(F11/E11,"-") -> - | I11: =IF(OR(ISBLANK(H10)=TRUE,ISBLANK(K10)=TRUE,ISBLANK(J10)=TRUE)," ",J10-K10) | J11: =IF(ISBLANK(H11)=TRUE," ",SUM(H11,I11)) | L11: =IFERROR(K11/J11,"-") -> -
B12: Nisan | C12: ='İşyeri ve Çalışan Bilgileri'!E24 -> 0 | D12: =IF(OR(ISBLANK(C11)=TRUE,ISBLANK(F11)=TRUE,ISBLANK(E11)=TRUE)," ",E11-F11) | E12: =IF(ISBLANK(C12)=TRUE," ",SUM(C12,D12)) -> 0 | G12: =IFERROR(F12/E12,"-") -> - | I12: =IF(OR(ISBLANK(H11)=TRUE,ISBLANK(K11)=TRUE,ISBLANK(J11)=TRUE)," ",J11-K11) | J12: =IF(ISBLANK(H12)=TRUE," ",SUM(H12,I12)) | L12: =IFERROR(K12/J12,"-") -> -
B13: Mayıs | C13: ='İşyeri ve Çalışan Bilgileri'!E25 -> 0 | D13: =IF(OR(ISBLANK(C12)=TRUE,ISBLANK(F12)=TRUE,ISBLANK(E12)=TRUE)," ",E12-F12) | E13: =IF(ISBLANK(C13)=TRUE," ",SUM(C13,D13)) -> 0 | G13: =IFERROR(F13/E13,"-") -> - | I13: =IF(OR(ISBLANK(H12)=TRUE,ISBLANK(K12)=TRUE,ISBLANK(J12)=TRUE)," ",J12-K12) | J13: =IF(ISBLANK(H13)=TRUE," ",SUM(H13,I13)) | L13: =IFERROR(K13/J13,"-") -> -
B14: Haziran | C14: ='İşyeri ve Çalışan Bilgileri'!E26 -> 0 | D14: =IF(OR(ISBLANK(C13)=TRUE,ISBLANK(F13)=TRUE,ISBLANK(E13)=TRUE)," ",E13-F13) | E14: =IF(ISBLANK(C14)=TRUE," ",SUM(C14,D14)) -> 0 | G14: =IFERROR(F14/E14,"-") -> - | I14: =IF(OR(ISBLANK(H13)=TRUE,ISBLANK(K13)=TRUE,ISBLANK(J13)=TRUE)," ",J13-K13) | J14: =IF(ISBLANK(H14)=TRUE," ",SUM(H14,I14)) | L14: =IFERROR(K14/J14,"-") -> -
B15: Temmuz | C15: ='İşyeri ve Çalışan Bilgileri'!E27 -> 0 | D15: =IF(OR(ISBLANK(C14)=TRUE,ISBLANK(F14)=TRUE,ISBLANK(E14)=TRUE)," ",E14-F14) | E15: =IF(ISBLANK(C15)=TRUE," ",SUM(C15,D15)) -> 0 | G15: =IFERROR(F15/E15,"-") -> - | I15: =IF(OR(ISBLANK(H14)=TRUE,ISBLANK(K14)=TRUE,ISBLANK(J14)=TRUE)," ",J14-K14) | J15: =IF(ISBLANK(H15)=TRUE," ",SUM(H15,I15)) | L15: =IFERROR(K15/J15,"-") -> -
B16: Ağustos | C16: ='İşyeri ve Çalışan Bilgileri'!E28 -> 0 | D16: =IF(OR(ISBLANK(C15)=TRUE,ISBLANK(F15)=TRUE,ISBLANK(E15)=TRUE)," ",E15-F15) | E16: =IF(ISBLANK(C16)=TRUE," ",SUM(C16,D16)) -> 0 | G16: =IFERROR(F16/E16,"-") -> - | I16: =IF(OR(ISBLANK(H15)=TRUE,ISBLANK(K15)=TRUE,ISBLANK(J15)=TRUE)," ",J15-K15) | J16: =IF(ISBLANK(H16)=TRUE," ",SUM(H16,I16)) | L16: =IFERROR(K16/J16,"-") -> -
B17: Eylül | C17: ='İşyeri ve Çalışan Bilgileri'!E29 -> 0 | D17: =IF(OR(ISBLANK(C16)=TRUE,ISBLANK(F16)=TRUE,ISBLANK(E16)=TRUE)," ",E16-F16) | E17: =IF(ISBLANK(C17)=TRUE," ",SUM(C17,D17)) -> 0 | G17: =IFERROR(F17/E17,"-") -> - | I17: =IF(OR(ISBLANK(H16)=TRUE,ISBLANK(K16)=TRUE,ISBLANK(J16)=TRUE)," ",J16-K16) | J17: =IF(ISBLANK(H17)=TRUE," ",SUM(H17,I17)) | L17: =IFERROR(K17/J17,"-") -> -
B18: Ekim | C18: ='İşyeri ve Çalışan Bilgileri'!E30 -> 0 | D18: =IF(OR(ISBLANK(C17)=TRUE,ISBLANK(F17)=TRUE,ISBLANK(E17)=TRUE)," ",E17-F17) | E18: =IF(ISBLANK(C18)=TRUE," ",SUM(C18,D18)) -> 0 | G18: =IFERROR(F18/E18,"-") -> - | I18: =IF(OR(ISBLANK(H17)=TRUE,ISBLANK(K17)=TRUE,ISBLANK(J17)=TRUE)," ",J17-K17) | J18: =IF(ISBLANK(H18)=TRUE," ",SUM(H18,I18)) | L18: =IFERROR(K18/J18,"-") -> -
B19: Kasım | C19: ='İşyeri ve Çalışan Bilgileri'!E31 -> 0 | D19: =IF(OR(ISBLANK(C18)=TRUE,ISBLANK(F18)=TRUE,ISBLANK(E18)=TRUE)," ",E18-F18) | E19: =IF(ISBLANK(C19)=TRUE," ",SUM(C19,D19)) -> 0 | G19: =IFERROR(F19/E19,"-") -> - | I19: =IF(OR(ISBLANK(H18)=TRUE,ISBLANK(K18)=TRUE,ISBLANK(J18)=TRUE)," ",J18-K18) | J19: =IF(ISBLANK(H19)=TRUE," ",SUM(H19,I19)) | L19: =IFERROR(K19/J19,"-") -> -
B20: Aralık | C20: ='İşyeri ve Çalışan Bilgileri'!E32 -> 0 | D20: =IF(OR(ISBLANK(C19)=TRUE,ISBLANK(F19)=TRUE,ISBLANK(E19)=TRUE)," ",E19-F19) | E20: =IF(ISBLANK(C20)=TRUE," ",SUM(C20,D20)) -> 0 | G20: =IFERROR(F20/E20,"-") -> - | I20: =IF(OR(ISBLANK(H19)=TRUE,ISBLANK(K19)=TRUE,ISBLANK(J19)=TRUE)," ",J19-K19) | J20: =IF(ISBLANK(H20)=TRUE," ",SUM(H20,I20)) | L20: =IFERROR(K20/J20,"-") -> -
B21: Ortalama / Toplam | E21: =SUM(E9:E20)-SUM(D9:D20) -> 45 | F21: =SUM(F9:F20) -> 0 | G21: =IFERROR(F21/E21,"-") -> 0 | J21: =SUM(J9:J20)-SUM(I9:I20) -> 0 | K21: =SUM(K9:K20) -> 0 | L21: =IFERROR(K21/J21,"-") -> -
B23: Alt İşveren Çalışanları İşe Giriş ve Periyodik Muayene
B24: Aylar | C24: İşe Giriş Muayenesi | H24: Periyodik Kontrol
C25: İlgili Dönemde İşe Giriş Yapan Çalışan Sayısı | D25: Önceki Dönemden Devreden İşe Giriş Muayenesi Gereken Çalışan Sayısı | E25: İlgili Dönemde İşe Giriş Muayenesi Gereken Toplam Çalışan Sayısı | F25: İşe Giriş Muayenesi Yapılan Çalışan Sayısı | G25: İşe Giriş Muayenesi Tamamlama Oranı | H25: İlgili Dönemde Periyodik Muayene Gereken Çalışan Sayısı | I25: Önceki Dönemden Devreden Periyodik Muayene Gereken Çalışan Sayısı | J25: İlgili Dönemde Periyodik Muayene Gereken Toplam Çalışan Sayısı | K25: Periyodik Muayenesi Yapılan Çalışan Sayısı | L25: Periyodik Muayene Tamamlama Oranı
B28: Ocak | C28: ='İşyeri ve Çalışan Bilgileri'!E38 -> 0 | D28: 0 | E28: =IF(ISBLANK(C28)=TRUE," ",SUM(C28,D28)) -> 0 | G28: =IFERROR(F28/E28,"-") -> - | I28: 0 | J28: =IF(ISBLANK(H28)=TRUE," ",SUM(H28,I28)) | L28: =IFERROR(K28/J28,"-") -> -
B29: Şubat | C29: ='İşyeri ve Çalışan Bilgileri'!E39 -> 0 | D29: =IF(OR(ISBLANK(C28)=TRUE,ISBLANK(F28)=TRUE,ISBLANK(E28)=TRUE)," ",E28-F28) | E29: =IF(ISBLANK(C29)=TRUE," ",SUM(C29,D29)) -> 0 | G29: =IFERROR(F29/E29,"-") -> - | I29: =IF(OR(ISBLANK(H28)=TRUE,ISBLANK(K28)=TRUE,ISBLANK(J28)=TRUE)," ",J28-K28) | J29: =IF(ISBLANK(H29)=TRUE," ",SUM(H29,I29)) | L29: =IFERROR(K29/J29,"-") -> -
B30: Mart | C30: ='İşyeri ve Çalışan Bilgileri'!E40 -> 0 | D30: =IF(OR(ISBLANK(C29)=TRUE,ISBLANK(F29)=TRUE,ISBLANK(E29)=TRUE)," ",E29-F29) | E30: =IF(ISBLANK(C30)=TRUE," ",SUM(C30,D30)) -> 0 | G30: =IFERROR(F30/E30,"-") -> - | I30: =IF(OR(ISBLANK(H29)=TRUE,ISBLANK(K29)=TRUE,ISBLANK(J29)=TRUE)," ",J29-K29) | J30: =IF(ISBLANK(H30)=TRUE," ",SUM(H30,I30)) | L30: =IFERROR(K30/J30,"-") -> -
B31: Nisan | C31: ='İşyeri ve Çalışan Bilgileri'!E41 -> 0 | D31: =IF(OR(ISBLANK(C30)=TRUE,ISBLANK(F30)=TRUE,ISBLANK(E30)=TRUE)," ",E30-F30) | E31: =IF(ISBLANK(C31)=TRUE," ",SUM(C31,D31)) -> 0 | G31: =IFERROR(F31/E31,"-") -> - | I31: =IF(OR(ISBLANK(H30)=TRUE,ISBLANK(K30)=TRUE,ISBLANK(J30)=TRUE)," ",J30-K30) | J31: =IF(ISBLANK(H31)=TRUE," ",SUM(H31,I31)) | L31: =IFERROR(K31/J31,"-") -> -
B32: Mayıs | C32: ='İşyeri ve Çalışan Bilgileri'!E42 -> 0 | D32: =IF(OR(ISBLANK(C31)=TRUE,ISBLANK(F31)=TRUE,ISBLANK(E31)=TRUE)," ",E31-F31) | E32: =IF(ISBLANK(C32)=TRUE," ",SUM(C32,D32)) -> 0 | G32: =IFERROR(F32/E32,"-") -> - | I32: =IF(OR(ISBLANK(H31)=TRUE,ISBLANK(K31)=TRUE,ISBLANK(J31)=TRUE)," ",J31-K31) | J32: =IF(ISBLANK(H32)=TRUE," ",SUM(H32,I32)) | L32: =IFERROR(K32/J32,"-") -> -
B33: Haziran | C33: ='İşyeri ve Çalışan Bilgileri'!E43 -> 0 | D33: =IF(OR(ISBLANK(C32)=TRUE,ISBLANK(F32)=TRUE,ISBLANK(E32)=TRUE)," ",E32-F32) | E33: =IF(ISBLANK(C33)=TRUE," ",SUM(C33,D33)) -> 0 | G33: =IFERROR(F33/E33,"-") -> - | I33: =IF(OR(ISBLANK(H32)=TRUE,ISBLANK(K32)=TRUE,ISBLANK(J32)=TRUE)," ",J32-K32) | J33: =IF(ISBLANK(H33)=TRUE," ",SUM(H33,I33)) | L33: =IFERROR(K33/J33,"-") -> -
B34: Temmuz | C34: ='İşyeri ve Çalışan Bilgileri'!E44 -> 0 | D34: =IF(OR(ISBLANK(C33)=TRUE,ISBLANK(F33)=TRUE,ISBLANK(E33)=TRUE)," ",E33-F33) | E34: =IF(ISBLANK(C34)=TRUE," ",SUM(C34,D34)) -> 0 | G34: =IFERROR(F34/E34,"-") -> - | I34: =IF(OR(ISBLANK(H33)=TRUE,ISBLANK(K33)=TRUE,ISBLANK(J33)=TRUE)," ",J33-K33) | J34: =IF(ISBLANK(H34)=TRUE," ",SUM(H34,I34)) | L34: =IFERROR(K34/J34,"-") -> -
B35: Ağustos | C35: ='İşyeri ve Çalışan Bilgileri'!E45 -> 0 | D35: =IF(OR(ISBLANK(C34)=TRUE,ISBLANK(F34)=TRUE,ISBLANK(E34)=TRUE)," ",E34-F34) | E35: =IF(ISBLANK(C35)=TRUE," ",SUM(C35,D35)) -> 0 | G35: =IFERROR(F35/E35,"-") -> - | I35: =IF(OR(ISBLANK(H34)=TRUE,ISBLANK(K34)=TRUE,ISBLANK(J34)=TRUE)," ",J34-K34) | J35: =IF(ISBLANK(H35)=TRUE," ",SUM(H35,I35)) | L35: =IFERROR(K35/J35,"-") -> -
B36: Eylül | C36: ='İşyeri ve Çalışan Bilgileri'!E46 -> 0 | D36: =IF(OR(ISBLANK(C35)=TRUE,ISBLANK(F35)=TRUE,ISBLANK(E35)=TRUE)," ",E35-F35) | E36: =IF(ISBLANK(C36)=TRUE," ",SUM(C36,D36)) -> 0 | G36: =IFERROR(F36/E36,"-") -> - | I36: =IF(OR(ISBLANK(H35)=TRUE,ISBLANK(K35)=TRUE,ISBLANK(J35)=TRUE)," ",J35-K35) | J36: =IF(ISBLANK(H36)=TRUE," ",SUM(H36,I36)) | L36: =IFERROR(K36/J36,"-") -> -
B37: Ekim | C37: ='İşyeri ve Çalışan Bilgileri'!E47 -> 0 | D37: =IF(OR(ISBLANK(C36)=TRUE,ISBLANK(F36)=TRUE,ISBLANK(E36)=TRUE)," ",E36-F36) | E37: =IF(ISBLANK(C37)=TRUE," ",SUM(C37,D37)) -> 0 | G37: =IFERROR(F37/E37,"-") -> - | I37: =IF(OR(ISBLANK(H36)=TRUE,ISBLANK(K36)=TRUE,ISBLANK(J36)=TRUE)," ",J36-K36) | J37: =IF(ISBLANK(H37)=TRUE," ",SUM(H37,I37)) | L37: =IFERROR(K37/J37,"-") -> -
B38: Kasım | C38: ='İşyeri ve Çalışan Bilgileri'!E48 -> 0 | D38: =IF(OR(ISBLANK(C37)=TRUE,ISBLANK(F37)=TRUE,ISBLANK(E37)=TRUE)," ",E37-F37) | E38: =IF(ISBLANK(C38)=TRUE," ",SUM(C38,D38)) -> 0 | G38: =IFERROR(F38/E38,"-") -> - | I38: =IF(OR(ISBLANK(H37)=TRUE,ISBLANK(K37)=TRUE,ISBLANK(J37)=TRUE)," ",J37-K37) | J38: =IF(ISBLANK(H38)=TRUE," ",SUM(H38,I38)) | L38: =IFERROR(K38/J38,"-") -> -
B39: Aralık | C39: ='İşyeri ve Çalışan Bilgileri'!E49 -> 0 | D39: =IF(OR(ISBLANK(C38)=TRUE,ISBLANK(F38)=TRUE,ISBLANK(E38)=TRUE)," ",E38-F38) | E39: =IF(ISBLANK(C39)=TRUE," ",SUM(C39,D39)) -> 0 | G39: =IFERROR(F39/E39,"-") -> - | I39: =IF(OR(ISBLANK(H38)=TRUE,ISBLANK(K38)=TRUE,ISBLANK(J38)=TRUE)," ",J38-K38) | J39: =IF(ISBLANK(H39)=TRUE," ",SUM(H39,I39)) | L39: =IFERROR(K39/J39,"-") -> -
B40: Ortalama / Toplam | E40: =SUM(E28:E39)-SUM(D28:D39) -> 0 | F40: =SUM(F28:F39) -> 0 | G40: =IFERROR(F40/E40,"-") -> - | J40: =SUM(J28:J39)-SUM(I28:I39) -> 0 | K40: =SUM(K28:K39) -> 0 | L40: =IFERROR(K40/J40,"-") -> -
B42: Açıklamalar: | C42: İşe Giriş Muayenesi bölümü için doldurulacak alanlar şu şekildedir: 1) Bir önceki yıldan eksik kalan olan çalışanlar için "Önceki Dönemden Devreden İşe Giriş Muayenesi Gereken Çalışan Sayısı" bilgisi Ocak ayına girilmelidir. 2) "İşe Giriş Muayenesi Yapılan Çalışan Sayısı" bilgisi tüm aylar için girilmelidir. | H42: Periyodik Kontrol bölümü için doldurulacak alanlar şu şekildedir: 1) "İlgili Dönemde Periyodik Muayene Gereken Çalışan Sayısı" bilgisi tüm aylar için girilmelidir. 2) Bir önceki yıldan eksik kalan olan çalışanlar için "Önceki Dönemden Devreden Periyodik Muayene Gereken Çalışan Sayısı" bilgisi Ocak ayına girilmelidir. 3) "Periyodik Muayenesi Yapılan Çalışan Sayısı" bilgisi tüm aylar için girilmelidir.

Sheet Sayfa1
A1: Olağan Dışı Olaylar
A2: Olay Türü | B2: Olayın Kök Nedeni
A3: Asansör Arızası | B3: Yapısal / İnşai nedenler
A4: Deprem | B4: Farkındalık Eksikliği
A5: Elektrik Kesintisi (Uzun Süreli) | B5: Mekanik Ekipman Kaynaklı Nedenler
A6: Hastane Çevresinde Olan Olaylar | B6: Elektronik/ Elektromekanik Ekipman Kaynaklı Nedenler
A7: Hırsızlık | B7: Sigara
A8: İnşaat/Renovasyon Kaynaklı Olaylar | B8: Medikal Cihaz Arızası
A9: İntihar | B9: Personel Eksikliği
A10: Kavga/Şiddet | B10: Personel Hatası
A11: Tehlikeli Madde Yayılımı | B11: Elektrikli el aletleri (Kettle, Kahve Makinesi vb.)
A12: Medikal Gaz Kesintisi | B12: Doğal Afet
A13: Pandemi | B13: Gaz Kaçağı
A14: Patlama | B14: Diğer
A15: Sabotaj
A16: Sel/Su baskını
A17: Silahlı Saldırı
A18: Yangın
A19: Yapısal Unsurlara Dair Olaylar
A20: Diğer
