Workbook
Name bas: #REF!
Name bas: #REF!
Name bas: #REF!
Name bas: #REF!
Name bas: #REF!
Name bas: #REF!
Name bas: #REF!
Name OLE_LINK1: 'İSG-F13-02'!#REF!

Sheet KAPAK
D22: ÖZEL ……………….. HASTANESİ
F49: HAZIRLAMA Tarihi EKLENECEK
A52: 1.AMAÇ Risklerin değerlendirilmesinde temel amaç, çalışanların, hasta ve yakınlarının, ziyaretçilerin, diğer kişilerin sağlığının korunması ve güvenliklerinin sağlanmasıdır. Risk değerlendirme, işle ilgili faaliyetlerden kaynaklanan ve etkilenecek kişilere ve çevreye olabilecek olası zararların en aza indirilmesine yardım eder. Bu kapsamda bu çalışmanın amacı .............................................. SAĞLIK HİZMETLERİ LTD. ŞTİ. Bünyesindeki ÖZEL ................................................................... HASTANESİ’ nde yapılan faaliyetlerin İş Sağlığı ve Güvenliği (İSG) açısından tehlikelerini ve riskleri tanımlamak, ortadan kaldırmak ve/veya azaltmak amacıyla gerekli tedbirleri belirlemektir. Risk değerlendirmesi sonucunda, işyerindeki gözlemlenen faaliyetlerindeki tehlikelerin neler olduğu ve kaza olma olasılığı ile olası kazaların boyutu/büyüklüğü hakkında bilgi sahibi olunacaktır.
A68: 2. YASAL DAYANAK Bu Risk değerlendirme raporu ; “6331 Sayılı İş Sağlığı Ve Güvenliği Kanunu” kapsamında 29.12.2012 tarih ve 28512 sayılı Rsmi Gazetede yayınlanmış olan ''İş Sağlığı Ve Güvenliği Risk Değerlendirmesi Yönetmeliği'' gereğince hazırlanmıştır.
A76: 3. İŞYERİ TANITIMI Hastane olarak hizmet vermekte olan Özel ...................................................................Hastanesi, ..................................................................... Ltd. Şti ' ye bağlı bir kuruluştur. Acil servis, Ambulans Hizmetleri, Poliklinikler, Yoğun Bakım Üniteleri, Ameliyathane ve Hasta servisleri ile bir çok konuda sağlık hizmeti vermektedir. Adres olarak .................................................................................................' de bulunmaktadır. İşveren Vekili ..........................................' dır.
A82: 4. GEÇERLİLİK TARİHİ Hastanemiz risk değerlendirmesi .............................. tarihi itibari ile yapılmış olup İş Sağlığı ve Güvenliği Risk Değerlendirmesi Yönetmeliğinin 12. Maddesinin 2. bendinde belirtilen durumlar olması durumunda yenilenir. Bu durumların olmaması durumunda da yine yönetmeliğin aynı maddesinin 1. bendine göre çok tehlikeli sınıfta olması sebebi ile ......................... yılına kadar geçerlidir.
A96: 5. RİSK DEĞERLENDİRME EKİBİ İş Sağlığı Ve Güvenliği Risk Değerlendirmesi Yönetmeliğinin 6. maddesine göre İşyerlerinde Risk Değerlendirmesi işverenin oluşturduğu bir ekip tarafından gerçekleştirilir. Bu kapsamda hastanemiz Risk Değerlendirme çalışmasında görevli kişiler de belirlenmiştir. Bunlar; ADI SOYADI GÖREVİ 6. KULLANILAN YÖNTEM VE UYGULAMA Risk değerlendirmesinde riskin büyüklüğünün hesaplanarak riskin kabul edilebilir olup olmadığına karar verilmelidir. Bunun belirlenmesi içinde kullanılan uluslararası risk değerlendirme metodları vardır. Bu çalışmada FİNE KİNNEY Risk değerlendirme metodu uygulanmıştır. Risk derecelendirme esasları aşağıdaki gibidir. RİSK PUANI: OLASILIK X FREKANS X ŞİDDET Risk Puanı, olasılık, frekans ve şiddet puanları çarpılarak bulunur. Hastanemiz risk değerlendirme çalışmalarında kullanılan yöntem ve uygulamaya ilişkin detaylar "İSG-P02 Tehlike Belirleme ve Risk Değerlendirme Prosedürü"nde anlatılmaktadır.

Sheet İSG-F13-02
A1: TEHLİKE BELİRLEME VE RİSK DEĞERLENDİRME TABLOSU (FINE KINNEY METODU) | AH1: OLASILIK | AI1: FREKANS | AJ1: ŞİDDET
A2: Değerlendirilen Bölüm | J2: Risk Değ. GüncellemeTarihi | P2: Geçerlilik Tarihi | AH2: 10 | AI2: 10 | AJ2: 100 | AP2: 0 | AQ2: 1 | AS2: Tehlikenin ortadan kaldırılması
A3: İşyeri Unvanı, Adresi | P3: Kullanılan Metod | Q3: Fine-Kinney Metodu | AH3: 6 | AI3: 6 | AJ3: 40 | AP3: 0.1 | AQ3: 2 | AS3: Mühendislik kontrolü
A4: No | B4: Tehlike Modülü | C4: Faaliyet | D4: Tehlike | E4: Tehlike Görseli | F4: Risk | G4: Sonuç/ Olası Etki Zarar | H4: Riskten Etkilenecek Kişiler | I4: Mevcut Durum (Tespit edilen riske ilişkin mevcut önlemler) | J4: MEVCUT | P4: İyileştirme Sorumlusu | Q4: Termin | R4: İYİLEŞTİRME | W4: İyileştirme Sonrası Görsel | X4: Sonuç | Y4: İlgili Mevzuat/Doküman | AH4: 3 | AI4: 3 | AJ4: 15 | AP4: 0.3 | AQ4: 3 | AS4: İdari Kontrol
J5: Olasılık | K5: Frekans | L5: Şiddet | M5: Risk Puanı | N5: Risk Seviyesi | O5: Alınacak Önlemler | R5: Olasılık | S5: Frekans | T5: Şiddet | U5: Risk Puanı | V5: Risk Seviyesi | AH5: 1 | AI5: 2 | AJ5: 7 | AP5: 0.5 | AQ5: 4 | AS5: KKD Kullanımı
A6: 1 | M6: =(L6*K6*J6) -> 0 | N6: =IF(AND(M6>=0,M6<20),"DÜŞÜK RİSK",IF(AND(M6>=20,M6<70),"OLASI RİSK",IF(AND(M6>=70,M6<200),"ÖNEMLİ RİSK",IF(AND(M6>=200,M6<400),"YÜKSEK RİSK",IF(M6>=400,"KABUL EDİLEMEZ RİSK",""))))) -> DÜŞÜK RİSK | U6: =(T6*S6*R6) -> 0 | V6: =IF(AND(U6>=0,U6<20),"DÜŞÜK RİSK",IF(AND(U6>=20,U6<70),"OLASI RİSK",IF(AND(U6>=70,U6<200),"ÖNEMLİ RİSK",IF(AND(U6>=200,U6<400),"YÜKSEK RİSK",IF(U6>=400,"KABUL EDİLEMEZ RİSK",""))))) -> DÜŞÜK RİSK | AH6: 0.5 | AI6: 1 | AJ6: 3 | AP6: 1 | AQ6: 5 | AS6: Hiçbir kontrol önlemi yok
A7: 8 | M7: =(L7*K7*J7) -> 0 | N7: =IF(AND(M7>=0,M7<20),"DÜŞÜK RİSK",IF(AND(M7>=20,M7<70),"OLASI RİSK",IF(AND(M7>=70,M7<200),"ÖNEMLİ RİSK",IF(AND(M7>=200,M7<400),"YÜKSEK RİSK",IF(M7>=400,"KABUL EDİLEMEZ RİSK",""))))) -> DÜŞÜK RİSK | U7: =(T7*S7*R7) -> 0 | V7: =IF(AND(U7>=0,U7<20),"DÜŞÜK RİSK",IF(AND(U7>=20,U7<70),"OLASI RİSK",IF(AND(U7>=70,U7<200),"ÖNEMLİ RİSK",IF(AND(U7>=200,U7<400),"YÜKSEK RİSK",IF(U7>=400,"KABUL EDİLEMEZ RİSK",""))))) -> DÜŞÜK RİSK
A8: 9 | M8: =(L8*K8*J8) -> 0 | N8: =IF(AND(M8>=0,M8<20),"DÜŞÜK RİSK",IF(AND(M8>=20,M8<70),"OLASI RİSK",IF(AND(M8>=70,M8<200),"ÖNEMLİ RİSK",IF(AND(M8>=200,M8<400),"YÜKSEK RİSK",IF(M8>=400,"KABUL EDİLEMEZ RİSK",""))))) -> DÜŞÜK RİSK | U8: =(T8*S8*R8) -> 0 | V8: =IF(AND(U8>=0,U8<20),"DÜŞÜK RİSK",IF(AND(U8>=20,U8<70),"OLASI RİSK",IF(AND(U8>=70,U8<200),"ÖNEMLİ RİSK",IF(AND(U8>=200,U8<400),"YÜKSEK RİSK",IF(U8>=400,"KABUL EDİLEMEZ RİSK",""))))) -> DÜŞÜK RİSK
A9: 10 | M9: =(L9*K9*J9) -> 0 | N9: =IF(AND(M9>=0,M9<20),"DÜŞÜK RİSK",IF(AND(M9>=20,M9<70),"OLASI RİSK",IF(AND(M9>=70,M9<200),"ÖNEMLİ RİSK",IF(AND(M9>=200,M9<400),"YÜKSEK RİSK",IF(M9>=400,"KABUL EDİLEMEZ RİSK",""))))) -> DÜŞÜK RİSK | U9: =(T9*S9*R9) -> 0 | V9: =IF(AND(U9>=0,U9<20),"DÜŞÜK RİSK",IF(AND(U9>=20,U9<70),"OLASI RİSK",IF(AND(U9>=70,U9<200),"ÖNEMLİ RİSK",IF(AND(U9>=200,U9<400),"YÜKSEK RİSK",IF(U9>=400,"KABUL EDİLEMEZ RİSK",""))))) -> DÜŞÜK RİSK
A10: 11 | M10: =(L10*K10*J10) -> 0 | N10: =IF(AND(M10>=0,M10<20),"DÜŞÜK RİSK",IF(AND(M10>=20,M10<70),"OLASI RİSK",IF(AND(M10>=70,M10<200),"ÖNEMLİ RİSK",IF(AND(M10>=200,M10<400),"YÜKSEK RİSK",IF(M10>=400,"KABUL EDİLEMEZ RİSK",""))))) -> DÜŞÜK RİSK | U10: =(T10*S10*R10) -> 0 | V10: =IF(AND(U10>=0,U10<20),"DÜŞÜK RİSK",IF(AND(U10>=20,U10<70),"OLASI RİSK",IF(AND(U10>=70,U10<200),"ÖNEMLİ RİSK",IF(AND(U10>=200,U10<400),"YÜKSEK RİSK",IF(U10>=400,"KABUL EDİLEMEZ RİSK",""))))) -> DÜŞÜK RİSK
A11: 12 | M11: =(L11*K11*J11) -> 0 | N11: =IF(AND(M11>=0,M11<20),"DÜŞÜK RİSK",IF(AND(M11>=20,M11<70),"OLASI RİSK",IF(AND(M11>=70,M11<200),"ÖNEMLİ RİSK",IF(AND(M11>=200,M11<400),"YÜKSEK RİSK",IF(M11>=400,"KABUL EDİLEMEZ RİSK",""))))) -> DÜŞÜK RİSK | U11: =(T11*S11*R11) -> 0 | V11: =IF(AND(U11>=0,U11<20),"DÜŞÜK RİSK",IF(AND(U11>=20,U11<70),"OLASI RİSK",IF(AND(U11>=70,U11<200),"ÖNEMLİ RİSK",IF(AND(U11>=200,U11<400),"YÜKSEK RİSK",IF(U11>=400,"KABUL EDİLEMEZ RİSK",""))))) -> DÜŞÜK RİSK
A12: 13 | M12: =(L12*K12*J12) -> 0 | N12: =IF(AND(M12>=0,M12<20),"DÜŞÜK RİSK",IF(AND(M12>=20,M12<70),"OLASI RİSK",IF(AND(M12>=70,M12<200),"ÖNEMLİ RİSK",IF(AND(M12>=200,M12<400),"YÜKSEK RİSK",IF(M12>=400,"KABUL EDİLEMEZ RİSK",""))))) -> DÜŞÜK RİSK | U12: =(T12*S12*R12) -> 0 | V12: =IF(AND(U12>=0,U12<20),"DÜŞÜK RİSK",IF(AND(U12>=20,U12<70),"OLASI RİSK",IF(AND(U12>=70,U12<200),"ÖNEMLİ RİSK",IF(AND(U12>=200,U12<400),"YÜKSEK RİSK",IF(U12>=400,"KABUL EDİLEMEZ RİSK",""))))) -> DÜŞÜK RİSK
A13: 14 | M13: =(L13*K13*J13) -> 0 | N13: =IF(AND(M13>=0,M13<20),"DÜŞÜK RİSK",IF(AND(M13>=20,M13<70),"OLASI RİSK",IF(AND(M13>=70,M13<200),"ÖNEMLİ RİSK",IF(AND(M13>=200,M13<400),"YÜKSEK RİSK",IF(M13>=400,"KABUL EDİLEMEZ RİSK",""))))) -> DÜŞÜK RİSK | U13: =(T13*S13*R13) -> 0 | V13: =IF(AND(U13>=0,U13<20),"DÜŞÜK RİSK",IF(AND(U13>=20,U13<70),"OLASI RİSK",IF(AND(U13>=70,U13<200),"ÖNEMLİ RİSK",IF(AND(U13>=200,U13<400),"YÜKSEK RİSK",IF(U13>=400,"KABUL EDİLEMEZ RİSK",""))))) -> DÜŞÜK RİSK
A14: 15 | M14: =(L14*K14*J14) -> 0 | N14: =IF(AND(M14>=0,M14<20),"DÜŞÜK RİSK",IF(AND(M14>=20,M14<70),"OLASI RİSK",IF(AND(M14>=70,M14<200),"ÖNEMLİ RİSK",IF(AND(M14>=200,M14<400),"YÜKSEK RİSK",IF(M14>=400,"KABUL EDİLEMEZ RİSK",""))))) -> DÜŞÜK RİSK | U14: =(T14*S14*R14) -> 0 | V14: =IF(AND(U14>=0,U14<20),"DÜŞÜK RİSK",IF(AND(U14>=20,U14<70),"OLASI RİSK",IF(AND(U14>=70,U14<200),"ÖNEMLİ RİSK",IF(AND(U14>=200,U14<400),"YÜKSEK RİSK",IF(U14>=400,"KABUL EDİLEMEZ RİSK",""))))) -> DÜŞÜK RİSK
A15: 16 | M15: =(L15*K15*J15) -> 0 | N15: =IF(AND(M15>=0,M15<20),"DÜŞÜK RİSK",IF(AND(M15>=20,M15<70),"OLASI RİSK",IF(AND(M15>=70,M15<200),"ÖNEMLİ RİSK",IF(AND(M15>=200,M15<400),"YÜKSEK RİSK",IF(M15>=400,"KABUL EDİLEMEZ RİSK",""))))) -> DÜŞÜK RİSK | U15: =(T15*S15*R15) -> 0 | V15: =IF(AND(U15>=0,U15<20),"DÜŞÜK RİSK",IF(AND(U15>=20,U15<70),"OLASI RİSK",IF(AND(U15>=70,U15<200),"ÖNEMLİ RİSK",IF(AND(U15>=200,U15<400),"YÜKSEK RİSK",IF(U15>=400,"KABUL EDİLEMEZ RİSK",""))))) -> DÜŞÜK RİSK
A16: 17 | M16: =(L16*K16*J16) -> 0 | N16: =IF(AND(M16>=0,M16<20),"DÜŞÜK RİSK",IF(AND(M16>=20,M16<70),"OLASI RİSK",IF(AND(M16>=70,M16<200),"ÖNEMLİ RİSK",IF(AND(M16>=200,M16<400),"YÜKSEK RİSK",IF(M16>=400,"KABUL EDİLEMEZ RİSK",""))))) -> DÜŞÜK RİSK | U16: =(T16*S16*R16) -> 0 | V16: =IF(AND(U16>=0,U16<20),"DÜŞÜK RİSK",IF(AND(U16>=20,U16<70),"OLASI RİSK",IF(AND(U16>=70,U16<200),"ÖNEMLİ RİSK",IF(AND(U16>=200,U16<400),"YÜKSEK RİSK",IF(U16>=400,"KABUL EDİLEMEZ RİSK",""))))) -> DÜŞÜK RİSK
A17: İŞVEREN/ VEKİLİ | E17: İŞ GÜVNLİĞİ UZMANI (LARI) | H17: İŞ YERİ HEKİMİ | N17: BAŞ ÇALIŞAN TEMSİLCİSİ | Q17: DESTEK ELEMAN | W17: KALİTE YÖNETİCİSİ
A19: DİĞER KATILIMCILAR / DİĞER EKİP ÜYELERİ (Ad Soyadı, Görevi, İmza)
A20: Ad Soyad
A21: İmza

Sheet Açıklamalar
A1: Risk Değerlendirme Kategorileri Kapsam ve Açıklamaları
A2: Risk değerlendirme çalışmaları aşağıda ifade edilen beş ana kategoride değenlendirilmektedir. Her kategori kendi içinde alt başlıkları kapsamaktadır. Değerlendirme sırasında açıklamalara uygun şekilde risklerin kategorize edilmesi gerekir.
A3: Kategori | B3: Alt Risk Kategorisi | C3: Açıklama
A4: Tıbbi Hizmetler | B4: • Hizmete erişim ile ilgili riskler • Hasta kabul süreci ile ilgili riskler • Tanı süreci ile ilgili riskler • Tedavi ve rehabilitasyon süreci ile ilgili riskler • Takip ve taburculuk süreci ile ilgili riskler • Tıbbi kayıt ve arşiv süreci ile ilgili riskler | C4: • Hizmete erişim ile ilgili riskler: İnternet sayfasında yer alan yanlış adres, randevu alınırken yaşanan hastane kaynaklı aksaklıklar v.b. • Hasta kabul süreci ile ilgili riskler: Kimlik bilgilerinin eksik veya hatalı girilmesi, kimlik doğrulamanın yapılmaması, yanlış polikliniğe yönlendirilme, hasta yatışında yaşanan sorunlar, sahte kimlikli hasta kabulü v.b. • Tanı süreci ile ilgili riskler: Hasta tetkiklerinin karışması, tetkik süreçlerine ilişkin hatalar, hatalı tanı girilmesi v.b. • Tedavi ve rehabilitasyon süreci ile ilgili riskler: Hastanın kliniğine özgü riskler, ilaç uygulama hataları, bakım sürecine ilişkin hatalar, hasta düşmeleri, hastalara takılan yüksek riskli kateterlerin yanlış kullanımı, cerrahi süreç hataları, hasta devrinde hastanın bilgilerinin eksik aktarılması, kurum içi konsültasyon istem sürecindeki aksaklıklar v.b. • Takip ve taburculuk süreci ile ilgili riskler: Hasta takibinde yaşanılan erişim sorunları, hasta ve hasta yakınına taburculuk eğitiminin eksik verilmesi v.b. • Tıbbi kayıt ve arşiv süreci ile ilgili riskler: Hasta kayıtlarına ulaşılamaması, eksik kayıt, arşiv hataları v.b.
A5: Yönetsel Hizmetler | B5: • İdari süreçler ile ilgili riskler • Finansal süreçler ile ilgili riskler • İtibar yönetimi • Paydaşlarla iletişim süreçlerine yönelik riskler • Bilgi yönetimi süreçleri ile ilgili riskler | C5: • İdari süreç ile ilgili riskler: Personel eksikliği, hasta ve çalışan geri bildirimlerinde olumsuz sonuçlar v.b. • Finansal süreç riskleri: İsraf, gereksiz malzeme kullanımı, hizmet alımı kapsamındaki gecikme v.b. • İtibar yönetimi: Sosyal sorumluluk projelerindeki yetersizlik v.b. • Paydaşlarla (112 acil sağlık hizmetleri, sosyal güvenlik kurumu, il sağlık müdürlüğü, aile sağlığı merkezi, tedarikçi, belediye, sosyal hizmet sunucusu v.b.) iletişim süreçlerine yönelik riskler • Bilgi yönetimi süreci riskleri (kişisel verilerin güvenliğinin ihlal edilerek, hasta sonucunun uygunsuz şekilde verilmesi v.b.)
A6: Tesis Güvenliği | B6: • Atık yönetimi sürecindeki riskler • Tıbbi cihaz ve malzeme yönetimi süreci riskleri • Diğer cihaz ve malzemelerin yönetim süreci riskleri • Yangın Güvenliği ile ilgili riskler • Altyapı Sistemleri ile ilgili riskler • İnşaat ve Renovasyon ile ilgili riskler • Acil Durum ve Afet Yönetimi ile ilgili riskler • Emniyet ile ilgili riskler | C6: • Tesis ile ilgili riskler: Tesis kaynaklı düşme olaylarına yönelik önlem alınmaması, acil çıkışlara yönelik yapılmayan düzenlemeler, asansörlerin tescil ve bakım sürecindeki aksaklıklar, acil çıkış kapısı veya yangın çıkışının önünde engel bulunması v.b. • Atık yönetimi sürecindeki riskler: Uygunsuz toplama, taşıma v.b. • Tıbbi cihaz ve malzeme yönetimi süreci riskleri: Bakım ve kalibrasyon eksikliğinden kaynaklanan hatalar, yetersiz malzeme riski, cihaz arızası kaynaklı hasta mağduriyeti, hemşire çağrı zili çalışmaması v.b. (Lazer ve optik radyasyon yayan cihazları dahil) • Diğer cihaz ve malzemelerin yönetim süreci riskleri: Düzenli yapılması gereken bakım-onarımlarda aksaklıklar, pencerelerin yarı açılabilir özellikte olmaması, prizlerde çocuk koruyucu bulunmaması sonucu elektrik çarpması, hasta odalarındaki malzeme ve cihazların arızası v.b. • Yangın güvenliği ile ilgili riskler: Hastanede aşağıda belirtilen konuları da kapsayan ve süreklilik arz eden bir yangın güvenliği risk değerlendirmesi gerçekleştirilmelidir. a) Yangın bölmelendirmeleri b) Duman bölmelendirmeleri c) Örneğin kirli çamaşır odaları, çöp toplama odaları ve oksijen depolama odaları gibi tehlikeli alanlar (ve bu alanların tavanlarının üzerindeki boşluklar) d) Yangın çıkışları e) Mutfakta yağlanmaya neden olan yemek pişirme araçları f) Çamaşır ve çöp şutları (şaftları) g) Acil durum için güç sistemleri (jeneratörler) ve ekipmanlar h) Tıbbi gaz ve vakum sisteminin parçaları i) Yanabilecek malzemelerin depolanması ve kullanımı (örneğin yanıcı sıvılar, yanıcı gazlar ve oksijen ve nitröz oksit gibi oksitleyici tıbbi gazlar) j) Cerrahi yangınların önlenmesine ve yönetilmesine prosedürler ve önlemler k) İnşaat, renovasyon veya yıkım projeleriyle ilişkili yangın tehlikeleri • Altyapı sistemleri ile ilgili riskler: Elektrik dağıtımı, güç; sıhhi tesisat; kazan/buhar; ısıtma, havalandırma ve iklimlendirme (HVAC); tıbbi gazlar; tıbbi/cerrahi vakum; atık yönetimi, iletişim ve veri sistemleri v.b. olacak şekilde güvenli sağlık bakımı verilebilmesi için hayati önem taşıyan hizmetleri destekleyen sistem ve ekipmanlardan kaynaklanan riskler. • İnşaat ve Renovasyon ile ilgili riskler: sistemleri ile ilgili riskler: İnşaat, renovasyon veya yıkım projeleriyle veya bir bakım çalışmasıyla ilişkili risklerin değerlendirilmesini kapsar (Örneğin inşaattan kaynaklanan gürültü ve titreşim konfor düzeylerini etkileyebildiği gibi inşaattan gelen toz ve kokular hava kalitesini bozabilir ve hastanın solunum fonksiyonları açısından risk oluşturabilir. Hastalara, çalışanlara, ziyaretçilere, bağımsız ticari işletmelere ve hastanedeki diğer kişilere yönelik risk, inşaat, renovasyon, yıkım ve bakım çalışmalarının kapsamına ve hasta bakımı, altyapı ve altyapı sistemleri üzerindeki etkisine göre değişiklik gösterebilir. Örnek olarak tıbbi gazlar üzerinde gerçekleştirilen bakım çalışmaları hasta bakımını etkileyebilir; ancak personel otoparkında yapılacak asfaltlama çalışmasının hastalara verilen bakım üzerinde bir etkisi olmayacaktır). • Emniyet ile ilgili riskler: Kuruluşun mallarının ve hasta, hasta yakınları, ziyaretçiler ve personelin zarara veya kayba karşı korunması anlamına gelmektedir. Örn: İş yerinde şiddet, bebek kaçırma, hırsızlık ve hastanedeki kısıtlı alanlara kilitsiz/emniyetsiz erişimdir.
A7: Çevre Güvenliği | B7: • Hava kirliliği oluşturabilecek unsurlar • Atıkların çevreye zarar vermesi • Çevreden hastaneye gelecek zararlar • Tehlikeli atıklardan oluşabilecek zararlar | C7: • Hava kirliliği oluşturabilecek unsurlar: Radyoaktif atıklardan kaynaklanan çevre zararı v.b. • Atıkların çevreye zarar vermesi: Uygunsuz depolama v.b. • Çevreden hastaneye gelecek zararlar: Hastane yakınında kirli su kaynağı, hava kirliliği veya gürültüye sebep olan iş yeri v.b. • Tehlikeli atıklardan oluşabilecek zararlar: Kimyasal atıkların oluşturduğu maruziyet v.b.
A8: İş Sağlığı ve Güvenliği | B8: • Güvenlik - Fiziksel Risk Etmenleri • Güvenlik - Biyolojik Risk Etmenleri • Güvenlik - Psikososyal Risk Etmenleri • Güvenlik- Ergonomik Risk Etmenleri • Tehlikeli Madde Yönetimi / Kimyasal Risk Etmenleri | C8: • Fiziksel risk etmenleri: Gürültü, titreşim, termal konfor şartları (aydınlatma, havalandırma, nem v.b.), ışık, radyasyon, basınç farklılıkları, toz gibi etkenlere maruziyet v.b. • Tehlikeli Maddeler / Kimyasal Risk Etmenleri: Çözücüler (solventler), metaller, gazlar, asit ve alkaliler, pestisidler gibi etkenlere maruziyet v.b. ile diğer tüm tehlikeli maddelere yönelik kullanım, temas, depolama ve bertaraf süreclerine ait riskler. • Biyolojik risk etmenleri: Bakteriler, virüsler, mantarlar, parazitler, böcekler gibi etkenlere ve bunlarla temas etmiş enfekte materyale maruziyet v.b. • Psikososyal risk etmenleri: Mobbing, şiddet, tükenmişlik, stres, yoğun çalışma v.b. • Ergonomik risk etmenleri: Uzun süreli ayakta veya oturarak çalışma, bilgisayar, monitör, çalışma koltuğu gibi cihaz/eşyaların postüre uygun özellik ve pozisyonda olmaması, ağır yük taşıma, eğilerek çalışma v.b. • Güvenlik ile ilgili riskler: Binanın, arazinin, tıbbi teknolojinin ve bilgi teknolojisinin, ekipmanların ve sistemlerin hastalar, hasta yakınları, çalışanlar ve ziyaretçiler açısından fiziksel bir risk teşkil etmesinin önlenmesi anlamına gelmektedir. Örnek olarak keskin ve kırık mobilyalar, kırık pencerelere, akan tavanlar, ergonomik riskler (örneğin hastaları veya ağır objeleri taşırken personelin maruz kaldığı riskler) ve (örneğin engebeli veya kaygan zemin veya tırabzan olmaması nedeniyle) düşme riski sayılabilir.

Sheet Fine Kinney Metodu
B1: FINE KINNEY METODU (Risk Skoru=Olasılık x Frekans x Şiddet)
B3: OLASILIK DEĞERİ | D3: ŞANS zararın gerçekleşme olasılığı | F3: FREKANS DEĞERİ | H3: FREKANS tehlikeye zaman içinde maruz kalma tekrarı | J3: ŞİDDET DEĞERİ | L3: ŞİDDET insan ve/veya çevre üzerinde yaratacağı tahmini zarar
B5: 10 | D5: Beklenir, kesin | F5: 10 | H5: Hemen Hemen Sürekli (bir saatte birkaç defa) | J5: 100 | L5: Birden Fazla Ölümlü Kaza / Çevresel Felaket
B7: 6 | D7: Yüksek, oldukça mümkün | F7: 6 | H7: Sık (günde bir veya birkaç defa) | J7: 40 | L7: Öldürücü Kaza / Ciddi Çevresel Zarar
B9: 3 | D9: Olası | F9: 3 | H9: Ara Sıra (haftada bir veya birkaç defa) | J9: 15 | L9: Kalıcı Hasar - Yaralanma, İş Kaybı / Çevresel Engel Oluşturma, Yakın Çevreden Şikayet
B11: 1 | D11: Mümkün fakat düşük | F11: 2 | H11: Sık Değil (ayda bir veya birkaç defa) | J11: 7 | L11: Önemli Hasar / Yaralanma, Dış İlkyardım İhtiyacı / Arazi Sınırları Dışında Çevresel Zarar
B13: 0.5 | D13: Beklenmez fakat mümkün | F13: 1 | H13: Seyrek (yılda birkaç defa) | J13: 3 | L13: Küçük Hasar/Yaralanma, Dahili İlk Yardım / Arazi İçinde Sınırlı Çevresel Zarar
B15: 0.2 | D15: Beklenmez | F15: 0.5 | H15: Çok Seyrek (yılda bir veya daha seyrek) | J15: 1 | L15: Ucuz Atlatma / Çevresel Zarar Yok
B17: RİSK DEĞERİ | F17: RİSK DEĞERLENDİRME SONUCU
B19: 400 < R | F19: Tolerans Gösterilemez Risk (hemen gerekli önlemler alınmalı / veya tesis, bina, çevrenin kapatılması düşünülmelidir)
B21: 200 < R < 400 | F21: Yüksek Risk (kısa dönemde iyileştirilmelidir (birkaç ay içinde))
B23: 70 < R < 200 | F23: Önemli Risk (uzun dönemde iyileştirilmelidir (yıl içinde))
B25: 20 < R < 70 | F25: Olası Risk (gözetim altında uygulanmalıdır)
B27: 20 < R < 70 | F27: Önemsiz Risk (önlem öncelikli değildir)

Sheet RD Fine Kinney (Birim Bazlı)
A1: TEHLİKE BELİRLEME VE RİSK DEĞERLENDİRME TABLOSU (FINE KINNEY METODU)
A3: Değerlendirilen Birim / Bölüm | H3: =IF(D3="Diğer","Diğer ise belirtiniz;","") | X3: Risk Değ. Güncelleme Tarihi | Y3: 44985 | AC3: Geçerlilik Tarihi | AE3: 45716
A4: İşyeri Unvanı, Adresi | AC4: Kullanılan Metod | AE4: Fine-Kinney Metodu
A6: No | B6: Tespit Tarihi | C6: Risk Kategorisi | D6: Alt Risk Kategorisi | F6: Alan | G6: Faaliyet | H6: Tehlike | I6: Risk | J6: Sonuç/ Olası Etki Zarar | K6: Riskten Etkilenecek Kişiler | L6: Mevcut Durum Açıklaması (Tespit edilen riske ilişkin mevcut önlemler) | M6: Mevcut Durum Görseli (Varsa tespit edilen riske ilişkin görsel) | N6: Mevcut Risk Skoru | S6: İyileştirme Planı | V6: İyileştirme Açıklaması (Tespit edilen riske ilişkin yapılan iyileştirmeler) | W6: İyileştirme Tamamlanma Tarihi | X6: İyileştirme Sonrası Görseli (Yapılan iyileştirme sonrasını gösteren görsel) | Y6: İyileştirme Sonrası Risk Skoru | AD6: İyileştirme Etkinlik Ölçümü | AG6: İlgili Mevzuat
N7: Olasılık | O7: Frekans | P7: Şiddet | Q7: Risk Puanı | R7: Risk Seviyesi | S7: Alınacak Önlemler / İyileştirici Faaliyet | T7: İyileştirme Sorumlusu | U7: Termin | Y7: Olasılık | Z7: Frekans | AA7: Şiddet | AB7: Risk Puanı | AC7: Risk Seviyesi | AD7: Etkinlik Ölçüm Yöntemi | AE7: İyileştirme Kontrol Sorumlusu | AF7: Sonuç
Q8: =IF(OR(ISBLANK(N8)=TRUE,ISBLANK(O8)=TRUE,ISBLANK(P8)=TRUE),"",PRODUCT(N8,O8,P8)) | R8: =IF(Q8="","",IF(AND(Q8>=0,Q8<20),"DÜŞÜK RİSK",IF(AND(Q8>=20,Q8<70),"OLASI RİSK",IF(AND(Q8>=70,Q8<200),"ÖNEMLİ RİSK",IF(AND(Q8>=200,Q8<400),"YÜKSEK RİSK",IF(Q8>=400,"KABUL EDİLEMEZ RİSK","")))))) | AB8: =IF(OR(ISBLANK(Y8)=TRUE,ISBLANK(Z8)=TRUE,ISBLANK(AA8)=TRUE),"",PRODUCT(Y8,Z8,AA8)) | AC8: =IF(AB8="","",IF(AND(AB8>=0,AB8<20),"DÜŞÜK RİSK",IF(AND(AB8>=20,AB8<70),"OLASI RİSK",IF(AND(AB8>=70,AB8<200),"ÖNEMLİ RİSK",IF(AND(AB8>=200,AB8<400),"YÜKSEK RİSK",IF(AB8>=400,"KABUL EDİLEMEZ RİSK",""))))))
Q9: =IF(OR(ISBLANK(N9)=TRUE,ISBLANK(O9)=TRUE,ISBLANK(P9)=TRUE),"",PRODUCT(N9,O9,P9)) | R9: =IF(Q9="","",IF(AND(Q9>=0,Q9<20),"DÜŞÜK RİSK",IF(AND(Q9>=20,Q9<70),"OLASI RİSK",IF(AND(Q9>=70,Q9<200),"ÖNEMLİ RİSK",IF(AND(Q9>=200,Q9<400),"YÜKSEK RİSK",IF(Q9>=400,"KABUL EDİLEMEZ RİSK","")))))) | AB9: =IF(OR(ISBLANK(Y9)=TRUE,ISBLANK(Z9)=TRUE,ISBLANK(AA9)=TRUE),"",PRODUCT(Y9,Z9,AA9)) | AC9: =IF(AB9="","",IF(AND(AB9>=0,AB9<20),"DÜŞÜK RİSK",IF(AND(AB9>=20,AB9<70),"OLASI RİSK",IF(AND(AB9>=70,AB9<200),"ÖNEMLİ RİSK",IF(AND(AB9>=200,AB9<400),"YÜKSEK RİSK",IF(AB9>=400,"KABUL EDİLEMEZ RİSK",""))))))
Q10: =IF(OR(ISBLANK(N10)=TRUE,ISBLANK(O10)=TRUE,ISBLANK(P10)=TRUE),"",PRODUCT(N10,O10,P10)) | R10: =IF(Q10="","",IF(AND(Q10>=0,Q10<20),"DÜŞÜK RİSK",IF(AND(Q10>=20,Q10<70),"OLASI RİSK",IF(AND(Q10>=70,Q10<200),"ÖNEMLİ RİSK",IF(AND(Q10>=200,Q10<400),"YÜKSEK RİSK",IF(Q10>=400,"KABUL EDİLEMEZ RİSK","")))))) | AB10: =IF(OR(ISBLANK(Y10)=TRUE,ISBLANK(Z10)=TRUE,ISBLANK(AA10)=TRUE),"",PRODUCT(Y10,Z10,AA10)) | AC10: =IF(AB10="","",IF(AND(AB10>=0,AB10<20),"DÜŞÜK RİSK",IF(AND(AB10>=20,AB10<70),"OLASI RİSK",IF(AND(AB10>=70,AB10<200),"ÖNEMLİ RİSK",IF(AND(AB10>=200,AB10<400),"YÜKSEK RİSK",IF(AB10>=400,"KABUL EDİLEMEZ RİSK",""))))))
Q11: =IF(OR(ISBLANK(N11)=TRUE,ISBLANK(O11)=TRUE,ISBLANK(P11)=TRUE),"",PRODUCT(N11,O11,P11)) | R11: =IF(Q11="","",IF(AND(Q11>=0,Q11<20),"DÜŞÜK RİSK",IF(AND(Q11>=20,Q11<70),"OLASI RİSK",IF(AND(Q11>=70,Q11<200),"ÖNEMLİ RİSK",IF(AND(Q11>=200,Q11<400),"YÜKSEK RİSK",IF(Q11>=400,"KABUL EDİLEMEZ RİSK","")))))) | AB11: =IF(OR(ISBLANK(Y11)=TRUE,ISBLANK(Z11)=TRUE,ISBLANK(AA11)=TRUE),"",PRODUCT(Y11,Z11,AA11)) | AC11: =IF(AB11="","",IF(AND(AB11>=0,AB11<20),"DÜŞÜK RİSK",IF(AND(AB11>=20,AB11<70),"OLASI RİSK",IF(AND(AB11>=70,AB11<200),"ÖNEMLİ RİSK",IF(AND(AB11>=200,AB11<400),"YÜKSEK RİSK",IF(AB11>=400,"KABUL EDİLEMEZ RİSK",""))))))
Q12: =IF(OR(ISBLANK(N12)=TRUE,ISBLANK(O12)=TRUE,ISBLANK(P12)=TRUE),"",PRODUCT(N12,O12,P12)) | R12: =IF(Q12="","",IF(AND(Q12>=0,Q12<20),"DÜŞÜK RİSK",IF(AND(Q12>=20,Q12<70),"OLASI RİSK",IF(AND(Q12>=70,Q12<200),"ÖNEMLİ RİSK",IF(AND(Q12>=200,Q12<400),"YÜKSEK RİSK",IF(Q12>=400,"KABUL EDİLEMEZ RİSK","")))))) | AB12: =IF(OR(ISBLANK(Y12)=TRUE,ISBLANK(Z12)=TRUE,ISBLANK(AA12)=TRUE),"",PRODUCT(Y12,Z12,AA12)) | AC12: =IF(AB12="","",IF(AND(AB12>=0,AB12<20),"DÜŞÜK RİSK",IF(AND(AB12>=20,AB12<70),"OLASI RİSK",IF(AND(AB12>=70,AB12<200),"ÖNEMLİ RİSK",IF(AND(AB12>=200,AB12<400),"YÜKSEK RİSK",IF(AB12>=400,"KABUL EDİLEMEZ RİSK",""))))))
Q13: =IF(OR(ISBLANK(N13)=TRUE,ISBLANK(O13)=TRUE,ISBLANK(P13)=TRUE),"",PRODUCT(N13,O13,P13)) | R13: =IF(Q13="","",IF(AND(Q13>=0,Q13<20),"DÜŞÜK RİSK",IF(AND(Q13>=20,Q13<70),"OLASI RİSK",IF(AND(Q13>=70,Q13<200),"ÖNEMLİ RİSK",IF(AND(Q13>=200,Q13<400),"YÜKSEK RİSK",IF(Q13>=400,"KABUL EDİLEMEZ RİSK","")))))) | AB13: =IF(OR(ISBLANK(Y13)=TRUE,ISBLANK(Z13)=TRUE,ISBLANK(AA13)=TRUE),"",PRODUCT(Y13,Z13,AA13)) | AC13: =IF(AB13="","",IF(AND(AB13>=0,AB13<20),"DÜŞÜK RİSK",IF(AND(AB13>=20,AB13<70),"OLASI RİSK",IF(AND(AB13>=70,AB13<200),"ÖNEMLİ RİSK",IF(AND(AB13>=200,AB13<400),"YÜKSEK RİSK",IF(AB13>=400,"KABUL EDİLEMEZ RİSK",""))))))
Q14: =IF(OR(ISBLANK(N14)=TRUE,ISBLANK(O14)=TRUE,ISBLANK(P14)=TRUE),"",PRODUCT(N14,O14,P14)) | R14: =IF(Q14="","",IF(AND(Q14>=0,Q14<20),"DÜŞÜK RİSK",IF(AND(Q14>=20,Q14<70),"OLASI RİSK",IF(AND(Q14>=70,Q14<200),"ÖNEMLİ RİSK",IF(AND(Q14>=200,Q14<400),"YÜKSEK RİSK",IF(Q14>=400,"KABUL EDİLEMEZ RİSK","")))))) | AB14: =IF(OR(ISBLANK(Y14)=TRUE,ISBLANK(Z14)=TRUE,ISBLANK(AA14)=TRUE),"",PRODUCT(Y14,Z14,AA14)) | AC14: =IF(AB14="","",IF(AND(AB14>=0,AB14<20),"DÜŞÜK RİSK",IF(AND(AB14>=20,AB14<70),"OLASI RİSK",IF(AND(AB14>=70,AB14<200),"ÖNEMLİ RİSK",IF(AND(AB14>=200,AB14<400),"YÜKSEK RİSK",IF(AB14>=400,"KABUL EDİLEMEZ RİSK",""))))))
Q15: =IF(OR(ISBLANK(N15)=TRUE,ISBLANK(O15)=TRUE,ISBLANK(P15)=TRUE),"",PRODUCT(N15,O15,P15)) | R15: =IF(Q15="","",IF(AND(Q15>=0,Q15<20),"DÜŞÜK RİSK",IF(AND(Q15>=20,Q15<70),"OLASI RİSK",IF(AND(Q15>=70,Q15<200),"ÖNEMLİ RİSK",IF(AND(Q15>=200,Q15<400),"YÜKSEK RİSK",IF(Q15>=400,"KABUL EDİLEMEZ RİSK","")))))) | AB15: =IF(OR(ISBLANK(Y15)=TRUE,ISBLANK(Z15)=TRUE,ISBLANK(AA15)=TRUE),"",PRODUCT(Y15,Z15,AA15)) | AC15: =IF(AB15="","",IF(AND(AB15>=0,AB15<20),"DÜŞÜK RİSK",IF(AND(AB15>=20,AB15<70),"OLASI RİSK",IF(AND(AB15>=70,AB15<200),"ÖNEMLİ RİSK",IF(AND(AB15>=200,AB15<400),"YÜKSEK RİSK",IF(AB15>=400,"KABUL EDİLEMEZ RİSK",""))))))
Q16: =IF(OR(ISBLANK(N16)=TRUE,ISBLANK(O16)=TRUE,ISBLANK(P16)=TRUE),"",PRODUCT(N16,O16,P16)) | R16: =IF(Q16="","",IF(AND(Q16>=0,Q16<20),"DÜŞÜK RİSK",IF(AND(Q16>=20,Q16<70),"OLASI RİSK",IF(AND(Q16>=70,Q16<200),"ÖNEMLİ RİSK",IF(AND(Q16>=200,Q16<400),"YÜKSEK RİSK",IF(Q16>=400,"KABUL EDİLEMEZ RİSK","")))))) | AB16: =IF(OR(ISBLANK(Y16)=TRUE,ISBLANK(Z16)=TRUE,ISBLANK(AA16)=TRUE),"",PRODUCT(Y16,Z16,AA16)) | AC16: =IF(AB16="","",IF(AND(AB16>=0,AB16<20),"DÜŞÜK RİSK",IF(AND(AB16>=20,AB16<70),"OLASI RİSK",IF(AND(AB16>=70,AB16<200),"ÖNEMLİ RİSK",IF(AND(AB16>=200,AB16<400),"YÜKSEK RİSK",IF(AB16>=400,"KABUL EDİLEMEZ RİSK",""))))))
Q17: =IF(OR(ISBLANK(N17)=TRUE,ISBLANK(O17)=TRUE,ISBLANK(P17)=TRUE),"",PRODUCT(N17,O17,P17)) | R17: =IF(Q17="","",IF(AND(Q17>=0,Q17<20),"DÜŞÜK RİSK",IF(AND(Q17>=20,Q17<70),"OLASI RİSK",IF(AND(Q17>=70,Q17<200),"ÖNEMLİ RİSK",IF(AND(Q17>=200,Q17<400),"YÜKSEK RİSK",IF(Q17>=400,"KABUL EDİLEMEZ RİSK","")))))) | AB17: =IF(OR(ISBLANK(Y17)=TRUE,ISBLANK(Z17)=TRUE,ISBLANK(AA17)=TRUE),"",PRODUCT(Y17,Z17,AA17)) | AC17: =IF(AB17="","",IF(AND(AB17>=0,AB17<20),"DÜŞÜK RİSK",IF(AND(AB17>=20,AB17<70),"OLASI RİSK",IF(AND(AB17>=70,AB17<200),"ÖNEMLİ RİSK",IF(AND(AB17>=200,AB17<400),"YÜKSEK RİSK",IF(AB17>=400,"KABUL EDİLEMEZ RİSK",""))))))
Q18: =IF(OR(ISBLANK(N18)=TRUE,ISBLANK(O18)=TRUE,ISBLANK(P18)=TRUE),"",PRODUCT(N18,O18,P18)) | R18: =IF(Q18="","",IF(AND(Q18>=0,Q18<20),"DÜŞÜK RİSK",IF(AND(Q18>=20,Q18<70),"OLASI RİSK",IF(AND(Q18>=70,Q18<200),"ÖNEMLİ RİSK",IF(AND(Q18>=200,Q18<400),"YÜKSEK RİSK",IF(Q18>=400,"KABUL EDİLEMEZ RİSK","")))))) | AB18: =IF(OR(ISBLANK(Y18)=TRUE,ISBLANK(Z18)=TRUE,ISBLANK(AA18)=TRUE),"",PRODUCT(Y18,Z18,AA18)) | AC18: =IF(AB18="","",IF(AND(AB18>=0,AB18<20),"DÜŞÜK RİSK",IF(AND(AB18>=20,AB18<70),"OLASI RİSK",IF(AND(AB18>=70,AB18<200),"ÖNEMLİ RİSK",IF(AND(AB18>=200,AB18<400),"YÜKSEK RİSK",IF(AB18>=400,"KABUL EDİLEMEZ RİSK",""))))))
Q19: =IF(OR(ISBLANK(N19)=TRUE,ISBLANK(O19)=TRUE,ISBLANK(P19)=TRUE),"",PRODUCT(N19,O19,P19)) | R19: =IF(Q19="","",IF(AND(Q19>=0,Q19<20),"DÜŞÜK RİSK",IF(AND(Q19>=20,Q19<70),"OLASI RİSK",IF(AND(Q19>=70,Q19<200),"ÖNEMLİ RİSK",IF(AND(Q19>=200,Q19<400),"YÜKSEK RİSK",IF(Q19>=400,"KABUL EDİLEMEZ RİSK","")))))) | AB19: =IF(OR(ISBLANK(Y19)=TRUE,ISBLANK(Z19)=TRUE,ISBLANK(AA19)=TRUE),"",PRODUCT(Y19,Z19,AA19)) | AC19: =IF(AB19="","",IF(AND(AB19>=0,AB19<20),"DÜŞÜK RİSK",IF(AND(AB19>=20,AB19<70),"OLASI RİSK",IF(AND(AB19>=70,AB19<200),"ÖNEMLİ RİSK",IF(AND(AB19>=200,AB19<400),"YÜKSEK RİSK",IF(AB19>=400,"KABUL EDİLEMEZ RİSK",""))))))
... Q100: =IF(OR(ISBLANK(N100)=TRUE,ISBLANK(O100)=TRUE,ISBLANK(P100)=TRUE),"",PRODUCT(N100,O100,P100)) | R100: =IF(Q100="","",IF(AND(Q100>=0,Q100<20),"DÜŞÜK RİSK",IF(AND(Q100>=20,Q100<70),"OLASI RİSK",IF(AND(Q100>=70,Q100<200),"ÖNEMLİ RİSK",IF(AND(Q100>=200,Q100<400),"YÜKSEK RİSK",IF(Q100>=400,"KABUL EDİLEMEZ RİSK","")))))) | AB100: =IF(OR(ISBLANK(Y100)=TRUE,ISBLANK(Z100)=TRUE,ISBLANK(AA100)=TRUE),"",PRODUCT(Y100,Z100,AA100)) | AC100: =IF(AB100="","",IF(AND(AB100>=0,AB100<20),"DÜŞÜK RİSK",IF(AND(AB100>=20,AB100<70),"OLASI RİSK",IF(AND(AB100>=70,AB100<200),"ÖNEMLİ RİSK",IF(AND(AB100>=200,AB100<400),"YÜKSEK RİSK",IF(AB100>=400,"KABUL EDİLEMEZ RİSK",""))))))
A101: RİSK DEĞERLENDİRME EKİBİ
A102: İşveren / İşveren Vekili | F102: İş Güvenliği Uzmanları | J102: İşyeri Hekimi | N102: Baş Çalışan Temsilcisi | T102: Destek Elemanı | W102: İlgili Birim Yöneticisi | AD102: İlgili Birim Sorumlusu
A104: Diğer Katılımcılar (Adı Soyadı, Görevi, Tarih, İmza)

Sheet Analiz (Birim Bazlı)
B2: KATEGORİ BAZLI RİSK DÜZEYİ DAĞILIMI
C5: Mevcut Durum | I5: İyileştirme Sonrası
B6: Kategoriler | C6: Düşük Risk | D6: Olası Risk | E6: Önemli Risk | F6: Yüksek Risk | G6: Kabul Edilemez Risk | H6: Toplam | I6: Düşük Risk | J6: Olası Risk | K6: Önemli Risk | L6: Yüksek Risk | M6: Kabul Edilemez Risk | N6: Toplam
B7: Çevre Güvenliği | C7: =COUNTIFS('RD Fine Kinney (Birim Bazlı)'!$C$8:$C$100,'Analiz (Birim Bazlı)'!$B7,'RD Fine Kinney (Birim Bazlı)'!$R$8:$R$100,'Analiz (Birim Bazlı)'!C$6) -> 0 | D7: =COUNTIFS('RD Fine Kinney (Birim Bazlı)'!$C$8:$C$100,'Analiz (Birim Bazlı)'!$B7,'RD Fine Kinney (Birim Bazlı)'!$R$8:$R$100,'Analiz (Birim Bazlı)'!D$6) -> 0 | E7: =COUNTIFS('RD Fine Kinney (Birim Bazlı)'!$C$8:$C$100,'Analiz (Birim Bazlı)'!$B7,'RD Fine Kinney (Birim Bazlı)'!$R$8:$R$100,'Analiz (Birim Bazlı)'!E$6) -> 0 | F7: =COUNTIFS('RD Fine Kinney (Birim Bazlı)'!$C$8:$C$100,'Analiz (Birim Bazlı)'!$B7,'RD Fine Kinney (Birim Bazlı)'!$R$8:$R$100,'Analiz (Birim Bazlı)'!F$6) -> 0 | G7: =COUNTIFS('RD Fine Kinney (Birim Bazlı)'!$C$8:$C$100,'Analiz (Birim Bazlı)'!$B7,'RD Fine Kinney (Birim Bazlı)'!$R$8:$R$100,'Analiz (Birim Bazlı)'!G$6) -> 0 | H7: =SUM(C7:G7) -> 0 | I7: =COUNTIFS('RD Fine Kinney (Birim Bazlı)'!$C$8:$C$100,'Analiz (Birim Bazlı)'!$B7,'RD Fine Kinney (Birim Bazlı)'!$AC$8:$AC$100,'Analiz (Birim Bazlı)'!I$6) -> 0 | J7: =COUNTIFS('RD Fine Kinney (Birim Bazlı)'!$C$8:$C$100,'Analiz (Birim Bazlı)'!$B7,'RD Fine Kinney (Birim Bazlı)'!$AC$8:$AC$100,'Analiz (Birim Bazlı)'!J$6) -> 0 | K7: =COUNTIFS('RD Fine Kinney (Birim Bazlı)'!$C$8:$C$100,'Analiz (Birim Bazlı)'!$B7,'RD Fine Kinney (Birim Bazlı)'!$AC$8:$AC$100,'Analiz (Birim Bazlı)'!K$6) -> 0 | L7: =COUNTIFS('RD Fine Kinney (Birim Bazlı)'!$C$8:$C$100,'Analiz (Birim Bazlı)'!$B7,'RD Fine Kinney (Birim Bazlı)'!$AC$8:$AC$100,'Analiz (Birim Bazlı)'!L$6) -> 0 | M7: =COUNTIFS('RD Fine Kinney (Birim Bazlı)'!$C$8:$C$100,'Analiz (Birim Bazlı)'!$B7,'RD Fine Kinney (Birim Bazlı)'!$AC$8:$AC$100,'Analiz (Birim Bazlı)'!M$6) -> 0 | N7: =SUM(I7:M7) -> 0
B8: Hava kirliliği oluşturabilecek unsurlar | C8: =COUNTIFS('RD Fine Kinney (Birim Bazlı)'!$D$8:$D$100,'Analiz (Birim Bazlı)'!$B8,'RD Fine Kinney (Birim Bazlı)'!$R$8:$R$100,'Analiz (Birim Bazlı)'!C$6) -> 0 | D8: =COUNTIFS('RD Fine Kinney (Birim Bazlı)'!$D$8:$D$100,'Analiz (Birim Bazlı)'!$B8,'RD Fine Kinney (Birim Bazlı)'!$R$8:$R$100,'Analiz (Birim Bazlı)'!D$6) -> 0 | E8: =COUNTIFS('RD Fine Kinney (Birim Bazlı)'!$D$8:$D$100,'Analiz (Birim Bazlı)'!$B8,'RD Fine Kinney (Birim Bazlı)'!$R$8:$R$100,'Analiz (Birim Bazlı)'!E$6) -> 0 | F8: =COUNTIFS('RD Fine Kinney (Birim Bazlı)'!$D$8:$D$100,'Analiz (Birim Bazlı)'!$B8,'RD Fine Kinney (Birim Bazlı)'!$R$8:$R$100,'Analiz (Birim Bazlı)'!F$6) -> 0 | G8: =COUNTIFS('RD Fine Kinney (Birim Bazlı)'!$D$8:$D$100,'Analiz (Birim Bazlı)'!$B8,'RD Fine Kinney (Birim Bazlı)'!$R$8:$R$100,'Analiz (Birim Bazlı)'!G$6) -> 0 | H8: =SUM(C8:G8) -> 0 | I8: =COUNTIFS('RD Fine Kinney (Birim Bazlı)'!$D$8:$D$100,'Analiz (Birim Bazlı)'!$B8,'RD Fine Kinney (Birim Bazlı)'!$AC$8:$AC$100,'Analiz (Birim Bazlı)'!I$6) -> 0 | J8: =COUNTIFS('RD Fine Kinney (Birim Bazlı)'!$D$8:$D$100,'Analiz (Birim Bazlı)'!$B8,'RD Fine Kinney (Birim Bazlı)'!$AC$8:$AC$100,'Analiz (Birim Bazlı)'!J$6) -> 0 | K8: =COUNTIFS('RD Fine Kinney (Birim Bazlı)'!$D$8:$D$100,'Analiz (Birim Bazlı)'!$B8,'RD Fine Kinney (Birim Bazlı)'!$AC$8:$AC$100,'Analiz (Birim Bazlı)'!K$6) -> 0 | L8: =COUNTIFS('RD Fine Kinney (Birim Bazlı)'!$D$8:$D$100,'Analiz (Birim Bazlı)'!$B8,'RD Fine Kinney (Birim Bazlı)'!$AC$8:$AC$100,'Analiz (Birim Bazlı)'!L$6) -> 0 | M8: =COUNTIFS('RD Fine Kinney (Birim Bazlı)'!$D$8:$D$100,'Analiz (Birim Bazlı)'!$B8,'RD Fine Kinney (Birim Bazlı)'!$AC$8:$AC$100,'Analiz (Birim Bazlı)'!M$6) -> 0 | N8: =SUM(I8:M8) -> 0
B9: Atıkların çevreye zarar vermesi | C9: =COUNTIFS('RD Fine Kinney (Birim Bazlı)'!$D$8:$D$100,'Analiz (Birim Bazlı)'!$B9,'RD Fine Kinney (Birim Bazlı)'!$R$8:$R$100,'Analiz (Birim Bazlı)'!C$6) -> 0 | D9: =COUNTIFS('RD Fine Kinney (Birim Bazlı)'!$D$8:$D$100,'Analiz (Birim Bazlı)'!$B9,'RD Fine Kinney (Birim Bazlı)'!$R$8:$R$100,'Analiz (Birim Bazlı)'!D$6) -> 0 | E9: =COUNTIFS('RD Fine Kinney (Birim Bazlı)'!$D$8:$D$100,'Analiz (Birim Bazlı)'!$B9,'RD Fine Kinney (Birim Bazlı)'!$R$8:$R$100,'Analiz (Birim Bazlı)'!E$6) -> 0 | F9: =COUNTIFS('RD Fine Kinney (Birim Bazlı)'!$D$8:$D$100,'Analiz (Birim Bazlı)'!$B9,'RD Fine Kinney (Birim Bazlı)'!$R$8:$R$100,'Analiz (Birim Bazlı)'!F$6) -> 0 | G9: =COUNTIFS('RD Fine Kinney (Birim Bazlı)'!$D$8:$D$100,'Analiz (Birim Bazlı)'!$B9,'RD Fine Kinney (Birim Bazlı)'!$R$8:$R$100,'Analiz (Birim Bazlı)'!G$6) -> 0 | H9: =SUM(C9:G9) -> 0 | I9: =COUNTIFS('RD Fine Kinney (Birim Bazlı)'!$D$8:$D$100,'Analiz (Birim Bazlı)'!$B9,'RD Fine Kinney (Birim Bazlı)'!$AC$8:$AC$100,'Analiz (Birim Bazlı)'!I$6) -> 0 | J9: =COUNTIFS('RD Fine Kinney (Birim Bazlı)'!$D$8:$D$100,'Analiz (Birim Bazlı)'!$B9,'RD Fine Kinney (Birim Bazlı)'!$AC$8:$AC$100,'Analiz (Birim Bazlı)'!J$6) -> 0 | K9: =COUNTIFS('RD Fine Kinney (Birim Bazlı)'!$D$8:$D$100,'Analiz (Birim Bazlı)'!$B9,'RD Fine Kinney (Birim Bazlı)'!$AC$8:$AC$100,'Analiz (Birim Bazlı)'!K$6) -> 0 | L9: =COUNTIFS('RD Fine Kinney (Birim Bazlı)'!$D$8:$D$100,'Analiz (Birim Bazlı)'!$B9,'RD Fine Kinney (Birim Bazlı)'!$AC$8:$AC$100,'Analiz (Birim Bazlı)'!L$6) -> 0 | M9: =COUNTIFS('RD Fine Kinney (Birim Bazlı)'!$D$8:$D$100,'Analiz (Birim Bazlı)'!$B9,'RD Fine Kinney (Birim Bazlı)'!$AC$8:$AC$100,'Analiz (Birim Bazlı)'!M$6) -> 0 | N9: =SUM(I9:M9) -> 0
B10: Çevreden hastaneye gelecek zararlar | C10: =COUNTIFS('RD Fine Kinney (Birim Bazlı)'!$D$8:$D$100,'Analiz (Birim Bazlı)'!$B10,'RD Fine Kinney (Birim Bazlı)'!$R$8:$R$100,'Analiz (Birim Bazlı)'!C$6) -> 0 | D10: =COUNTIFS('RD Fine Kinney (Birim Bazlı)'!$D$8:$D$100,'Analiz (Birim Bazlı)'!$B10,'RD Fine Kinney (Birim Bazlı)'!$R$8:$R$100,'Analiz (Birim Bazlı)'!D$6) -> 0 | E10: =COUNTIFS('RD Fine Kinney (Birim Bazlı)'!$D$8:$D$100,'Analiz (Birim Bazlı)'!$B10,'RD Fine Kinney (Birim Bazlı)'!$R$8:$R$100,'Analiz (Birim Bazlı)'!E$6) -> 0 | F10: =COUNTIFS('RD Fine Kinney (Birim Bazlı)'!$D$8:$D$100,'Analiz (Birim Bazlı)'!$B10,'RD Fine Kinney (Birim Bazlı)'!$R$8:$R$100,'Analiz (Birim Bazlı)'!F$6) -> 0 | G10: =COUNTIFS('RD Fine Kinney (Birim Bazlı)'!$D$8:$D$100,'Analiz (Birim Bazlı)'!$B10,'RD Fine Kinney (Birim Bazlı)'!$R$8:$R$100,'Analiz (Birim Bazlı)'!G$6) -> 0 | H10: =SUM(C10:G10) -> 0 | I10: =COUNTIFS('RD Fine Kinney (Birim Bazlı)'!$D$8:$D$100,'Analiz (Birim Bazlı)'!$B10,'RD Fine Kinney (Birim Bazlı)'!$AC$8:$AC$100,'Analiz (Birim Bazlı)'!I$6) -> 0 | J10: =COUNTIFS('RD Fine Kinney (Birim Bazlı)'!$D$8:$D$100,'Analiz (Birim Bazlı)'!$B10,'RD Fine Kinney (Birim Bazlı)'!$AC$8:$AC$100,'Analiz (Birim Bazlı)'!J$6) -> 0 | K10: =COUNTIFS('RD Fine Kinney (Birim Bazlı)'!$D$8:$D$100,'Analiz (Birim Bazlı)'!$B10,'RD Fine Kinney (Birim Bazlı)'!$AC$8:$AC$100,'Analiz (Birim Bazlı)'!K$6) -> 0 | L10: =COUNTIFS('RD Fine Kinney (Birim Bazlı)'!$D$8:$D$100,'Analiz (Birim Bazlı)'!$B10,'RD Fine Kinney (Birim Bazlı)'!$AC$8:$AC$100,'Analiz (Birim Bazlı)'!L$6) -> 0 | M10: =COUNTIFS('RD Fine Kinney (Birim Bazlı)'!$D$8:$D$100,'Analiz (Birim Bazlı)'!$B10,'RD Fine Kinney (Birim Bazlı)'!$AC$8:$AC$100,'Analiz (Birim Bazlı)'!M$6) -> 0 | N10: =SUM(I10:M10) -> 0
B11: Tehlikeli atıklardan oluşabilecek zararlar | C11: =COUNTIFS('RD Fine Kinney (Birim Bazlı)'!$D$8:$D$100,'Analiz (Birim Bazlı)'!$B11,'RD Fine Kinney (Birim Bazlı)'!$R$8:$R$100,'Analiz (Birim Bazlı)'!C$6) -> 0 | D11: =COUNTIFS('RD Fine Kinney (Birim Bazlı)'!$D$8:$D$100,'Analiz (Birim Bazlı)'!$B11,'RD Fine Kinney (Birim Bazlı)'!$R$8:$R$100,'Analiz (Birim Bazlı)'!D$6) -> 0 | E11: =COUNTIFS('RD Fine Kinney (Birim Bazlı)'!$D$8:$D$100,'Analiz (Birim Bazlı)'!$B11,'RD Fine Kinney (Birim Bazlı)'!$R$8:$R$100,'Analiz (Birim Bazlı)'!E$6) -> 0 | F11: =COUNTIFS('RD Fine Kinney (Birim Bazlı)'!$D$8:$D$100,'Analiz (Birim Bazlı)'!$B11,'RD Fine Kinney (Birim Bazlı)'!$R$8:$R$100,'Analiz (Birim Bazlı)'!F$6) -> 0 | G11: =COUNTIFS('RD Fine Kinney (Birim Bazlı)'!$D$8:$D$100,'Analiz (Birim Bazlı)'!$B11,'RD Fine Kinney (Birim Bazlı)'!$R$8:$R$100,'Analiz (Birim Bazlı)'!G$6) -> 0 | H11: =SUM(C11:G11) -> 0 | I11: =COUNTIFS('RD Fine Kinney (Birim Bazlı)'!$D$8:$D$100,'Analiz (Birim Bazlı)'!$B11,'RD Fine Kinney (Birim Bazlı)'!$AC$8:$AC$100,'Analiz (Birim Bazlı)'!I$6) -> 0 | J11: =COUNTIFS('RD Fine Kinney (Birim Bazlı)'!$D$8:$D$100,'Analiz (Birim Bazlı)'!$B11,'RD Fine Kinney (Birim Bazlı)'!$AC$8:$AC$100,'Analiz (Birim Bazlı)'!J$6) -> 0 | K11: =COUNTIFS('RD Fine Kinney (Birim Bazlı)'!$D$8:$D$100,'Analiz (Birim Bazlı)'!$B11,'RD Fine Kinney (Birim Bazlı)'!$AC$8:$AC$100,'Analiz (Birim Bazlı)'!K$6) -> 0 | L11: =COUNTIFS('RD Fine Kinney (Birim Bazlı)'!$D$8:$D$100,'Analiz (Birim Bazlı)'!$B11,'RD Fine Kinney (Birim Bazlı)'!$AC$8:$AC$100,'Analiz (Birim Bazlı)'!L$6) -> 0 | M11: =COUNTIFS('RD Fine Kinney (Birim Bazlı)'!$D$8:$D$100,'Analiz (Birim Bazlı)'!$B11,'RD Fine Kinney (Birim Bazlı)'!$AC$8:$AC$100,'Analiz (Birim Bazlı)'!M$6) -> 0 | N11: =SUM(I11:M11) -> 0
B12: İş Sağlığı ve Güvenliği | C12: =COUNTIFS('RD Fine Kinney (Birim Bazlı)'!$C$8:$C$100,'Analiz (Birim Bazlı)'!$B12,'RD Fine Kinney (Birim Bazlı)'!$R$8:$R$100,'Analiz (Birim Bazlı)'!C$6) -> 0 | D12: =COUNTIFS('RD Fine Kinney (Birim Bazlı)'!$C$8:$C$100,'Analiz (Birim Bazlı)'!$B12,'RD Fine Kinney (Birim Bazlı)'!$R$8:$R$100,'Analiz (Birim Bazlı)'!D$6) -> 0 | E12: =COUNTIFS('RD Fine Kinney (Birim Bazlı)'!$C$8:$C$100,'Analiz (Birim Bazlı)'!$B12,'RD Fine Kinney (Birim Bazlı)'!$R$8:$R$100,'Analiz (Birim Bazlı)'!E$6) -> 0 | F12: =COUNTIFS('RD Fine Kinney (Birim Bazlı)'!$C$8:$C$100,'Analiz (Birim Bazlı)'!$B12,'RD Fine Kinney (Birim Bazlı)'!$R$8:$R$100,'Analiz (Birim Bazlı)'!F$6) -> 0 | G12: =COUNTIFS('RD Fine Kinney (Birim Bazlı)'!$C$8:$C$100,'Analiz (Birim Bazlı)'!$B12,'RD Fine Kinney (Birim Bazlı)'!$R$8:$R$100,'Analiz (Birim Bazlı)'!G$6) -> 0 | H12: =SUM(C12:G12) -> 0 | I12: =COUNTIFS('RD Fine Kinney (Birim Bazlı)'!$C$8:$C$100,'Analiz (Birim Bazlı)'!$B12,'RD Fine Kinney (Birim Bazlı)'!$AC$8:$AC$100,'Analiz (Birim Bazlı)'!I$6) -> 0 | J12: =COUNTIFS('RD Fine Kinney (Birim Bazlı)'!$C$8:$C$100,'Analiz (Birim Bazlı)'!$B12,'RD Fine Kinney (Birim Bazlı)'!$AC$8:$AC$100,'Analiz (Birim Bazlı)'!J$6) -> 0 | K12: =COUNTIFS('RD Fine Kinney (Birim Bazlı)'!$C$8:$C$100,'Analiz (Birim Bazlı)'!$B12,'RD Fine Kinney (Birim Bazlı)'!$AC$8:$AC$100,'Analiz (Birim Bazlı)'!K$6) -> 0 | L12: =COUNTIFS('RD Fine Kinney (Birim Bazlı)'!$C$8:$C$100,'Analiz (Birim Bazlı)'!$B12,'RD Fine Kinney (Birim Bazlı)'!$AC$8:$AC$100,'Analiz (Birim Bazlı)'!L$6) -> 0 | M12: =COUNTIFS('RD Fine Kinney (Birim Bazlı)'!$C$8:$C$100,'Analiz (Birim Bazlı)'!$B12,'RD Fine Kinney (Birim Bazlı)'!$AC$8:$AC$100,'Analiz (Birim Bazlı)'!M$6) -> 0 | N12: =SUM(I12:M12) -> 0
B13: Güvenlik - Fiziksel Risk Etmenleri | C13: =COUNTIFS('RD Fine Kinney (Birim Bazlı)'!$D$8:$D$100,'Analiz (Birim Bazlı)'!$B13,'RD Fine Kinney (Birim Bazlı)'!$R$8:$R$100,'Analiz (Birim Bazlı)'!C$6) -> 0 | D13: =COUNTIFS('RD Fine Kinney (Birim Bazlı)'!$D$8:$D$100,'Analiz (Birim Bazlı)'!$B13,'RD Fine Kinney (Birim Bazlı)'!$R$8:$R$100,'Analiz (Birim Bazlı)'!D$6) -> 0 | E13: =COUNTIFS('RD Fine Kinney (Birim Bazlı)'!$D$8:$D$100,'Analiz (Birim Bazlı)'!$B13,'RD Fine Kinney (Birim Bazlı)'!$R$8:$R$100,'Analiz (Birim Bazlı)'!E$6) -> 0 | F13: =COUNTIFS('RD Fine Kinney (Birim Bazlı)'!$D$8:$D$100,'Analiz (Birim Bazlı)'!$B13,'RD Fine Kinney (Birim Bazlı)'!$R$8:$R$100,'Analiz (Birim Bazlı)'!F$6) -> 0 | G13: =COUNTIFS('RD Fine Kinney (Birim Bazlı)'!$D$8:$D$100,'Analiz (Birim Bazlı)'!$B13,'RD Fine Kinney (Birim Bazlı)'!$R$8:$R$100,'Analiz (Birim Bazlı)'!G$6) -> 0 | H13: =SUM(C13:G13) -> 0 | I13: =COUNTIFS('RD Fine Kinney (Birim Bazlı)'!$D$8:$D$100,'Analiz (Birim Bazlı)'!$B13,'RD Fine Kinney (Birim Bazlı)'!$AC$8:$AC$100,'Analiz (Birim Bazlı)'!I$6) -> 0 | J13: =COUNTIFS('RD Fine Kinney (Birim Bazlı)'!$D$8:$D$100,'Analiz (Birim Bazlı)'!$B13,'RD Fine Kinney (Birim Bazlı)'!$AC$8:$AC$100,'Analiz (Birim Bazlı)'!J$6) -> 0 | K13: =COUNTIFS('RD Fine Kinney (Birim Bazlı)'!$D$8:$D$100,'Analiz (Birim Bazlı)'!$B13,'RD Fine Kinney (Birim Bazlı)'!$AC$8:$AC$100,'Analiz (Birim Bazlı)'!K$6) -> 0 | L13: =COUNTIFS('RD Fine Kinney (Birim Bazlı)'!$D$8:$D$100,'Analiz (Birim Bazlı)'!$B13,'RD Fine Kinney (Birim Bazlı)'!$AC$8:$AC$100,'Analiz (Birim Bazlı)'!L$6) -> 0 | M13: =COUNTIFS('RD Fine Kinney (Birim Bazlı)'!$D$8:$D$100,'Analiz (Birim Bazlı)'!$B13,'RD Fine Kinney (Birim Bazlı)'!$AC$8:$AC$100,'Analiz (Birim Bazlı)'!M$6) -> 0 | N13: =SUM(I13:M13) -> 0
B14: Güvenlik - Biyolojik Risk Etmenleri | C14: =COUNTIFS('RD Fine Kinney (Birim Bazlı)'!$D$8:$D$100,'Analiz (Birim Bazlı)'!$B14,'RD Fine Kinney (Birim Bazlı)'!$R$8:$R$100,'Analiz (Birim Bazlı)'!C$6) -> 0 | D14: =COUNTIFS('RD Fine Kinney (Birim Bazlı)'!$D$8:$D$100,'Analiz (Birim Bazlı)'!$B14,'RD Fine Kinney (Birim Bazlı)'!$R$8:$R$100,'Analiz (Birim Bazlı)'!D$6) -> 0 | E14: =COUNTIFS('RD Fine Kinney (Birim Bazlı)'!$D$8:$D$100,'Analiz (Birim Bazlı)'!$B14,'RD Fine Kinney (Birim Bazlı)'!$R$8:$R$100,'Analiz (Birim Bazlı)'!E$6) -> 0 | F14: =COUNTIFS('RD Fine Kinney (Birim Bazlı)'!$D$8:$D$100,'Analiz (Birim Bazlı)'!$B14,'RD Fine Kinney (Birim Bazlı)'!$R$8:$R$100,'Analiz (Birim Bazlı)'!F$6) -> 0 | G14: =COUNTIFS('RD Fine Kinney (Birim Bazlı)'!$D$8:$D$100,'Analiz (Birim Bazlı)'!$B14,'RD Fine Kinney (Birim Bazlı)'!$R$8:$R$100,'Analiz (Birim Bazlı)'!G$6) -> 0 | H14: =SUM(C14:G14) -> 0 | I14: =COUNTIFS('RD Fine Kinney (Birim Bazlı)'!$D$8:$D$100,'Analiz (Birim Bazlı)'!$B14,'RD Fine Kinney (Birim Bazlı)'!$AC$8:$AC$100,'Analiz (Birim Bazlı)'!I$6) -> 0 | J14: =COUNTIFS('RD Fine Kinney (Birim Bazlı)'!$D$8:$D$100,'Analiz (Birim Bazlı)'!$B14,'RD Fine Kinney (Birim Bazlı)'!$AC$8:$AC$100,'Analiz (Birim Bazlı)'!J$6) -> 0 | K14: =COUNTIFS('RD Fine Kinney (Birim Bazlı)'!$D$8:$D$100,'Analiz (Birim Bazlı)'!$B14,'RD Fine Kinney (Birim Bazlı)'!$AC$8:$AC$100,'Analiz (Birim Bazlı)'!K$6) -> 0 | L14: =COUNTIFS('RD Fine Kinney (Birim Bazlı)'!$D$8:$D$100,'Analiz (Birim Bazlı)'!$B14,'RD Fine Kinney (Birim Bazlı)'!$AC$8:$AC$100,'Analiz (Birim Bazlı)'!L$6) -> 0 | M14: =COUNTIFS('RD Fine Kinney (Birim Bazlı)'!$D$8:$D$100,'Analiz (Birim Bazlı)'!$B14,'RD Fine Kinney (Birim Bazlı)'!$AC$8:$AC$100,'Analiz (Birim Bazlı)'!M$6) -> 0 | N14: =SUM(I14:M14) -> 0
B15: Güvenlik - Psikososyal Risk Etmenleri | C15: =COUNTIFS('RD Fine Kinney (Birim Bazlı)'!$D$8:$D$100,'Analiz (Birim Bazlı)'!$B15,'RD Fine Kinney (Birim Bazlı)'!$R$8:$R$100,'Analiz (Birim Bazlı)'!C$6) -> 0 | D15: =COUNTIFS('RD Fine Kinney (Birim Bazlı)'!$D$8:$D$100,'Analiz (Birim Bazlı)'!$B15,'RD Fine Kinney (Birim Bazlı)'!$R$8:$R$100,'Analiz (Birim Bazlı)'!D$6) -> 0 | E15: =COUNTIFS('RD Fine Kinney (Birim Bazlı)'!$D$8:$D$100,'Analiz (Birim Bazlı)'!$B15,'RD Fine Kinney (Birim Bazlı)'!$R$8:$R$100,'Analiz (Birim Bazlı)'!E$6) -> 0 | F15: =COUNTIFS('RD Fine Kinney (Birim Bazlı)'!$D$8:$D$100,'Analiz (Birim Bazlı)'!$B15,'RD Fine Kinney (Birim Bazlı)'!$R$8:$R$100,'Analiz (Birim Bazlı)'!F$6) -> 0 | G15: =COUNTIFS('RD Fine Kinney (Birim Bazlı)'!$D$8:$D$100,'Analiz (Birim Bazlı)'!$B15,'RD Fine Kinney (Birim Bazlı)'!$R$8:$R$100,'Analiz (Birim Bazlı)'!G$6) -> 0 | H15: =SUM(C15:G15) -> 0 | I15: =COUNTIFS('RD Fine Kinney (Birim Bazlı)'!$D$8:$D$100,'Analiz (Birim Bazlı)'!$B15,'RD Fine Kinney (Birim Bazlı)'!$AC$8:$AC$100,'Analiz (Birim Bazlı)'!I$6) -> 0 | J15: =COUNTIFS('RD Fine Kinney (Birim Bazlı)'!$D$8:$D$100,'Analiz (Birim Bazlı)'!$B15,'RD Fine Kinney (Birim Bazlı)'!$AC$8:$AC$100,'Analiz (Birim Bazlı)'!J$6) -> 0 | K15: =COUNTIFS('RD Fine Kinney (Birim Bazlı)'!$D$8:$D$100,'Analiz (Birim Bazlı)'!$B15,'RD Fine Kinney (Birim Bazlı)'!$AC$8:$AC$100,'Analiz (Birim Bazlı)'!K$6) -> 0 | L15: =COUNTIFS('RD Fine Kinney (Birim Bazlı)'!$D$8:$D$100,'Analiz (Birim Bazlı)'!$B15,'RD Fine Kinney (Birim Bazlı)'!$AC$8:$AC$100,'Analiz (Birim Bazlı)'!L$6) -> 0 | M15: =COUNTIFS('RD Fine Kinney (Birim Bazlı)'!$D$8:$D$100,'Analiz (Birim Bazlı)'!$B15,'RD Fine Kinney (Birim Bazlı)'!$AC$8:$AC$100,'Analiz (Birim Bazlı)'!M$6) -> 0 | N15: =SUM(I15:M15) -> 0
B16: Güvenlik - Ergonomik Risk Etmenler | C16: =COUNTIFS('RD Fine Kinney (Birim Bazlı)'!$D$8:$D$100,'Analiz (Birim Bazlı)'!$B16,'RD Fine Kinney (Birim Bazlı)'!$R$8:$R$100,'Analiz (Birim Bazlı)'!C$6) -> 0 | D16: =COUNTIFS('RD Fine Kinney (Birim Bazlı)'!$D$8:$D$100,'Analiz (Birim Bazlı)'!$B16,'RD Fine Kinney (Birim Bazlı)'!$R$8:$R$100,'Analiz (Birim Bazlı)'!D$6) -> 0 | E16: =COUNTIFS('RD Fine Kinney (Birim Bazlı)'!$D$8:$D$100,'Analiz (Birim Bazlı)'!$B16,'RD Fine Kinney (Birim Bazlı)'!$R$8:$R$100,'Analiz (Birim Bazlı)'!E$6) -> 0 | F16: =COUNTIFS('RD Fine Kinney (Birim Bazlı)'!$D$8:$D$100,'Analiz (Birim Bazlı)'!$B16,'RD Fine Kinney (Birim Bazlı)'!$R$8:$R$100,'Analiz (Birim Bazlı)'!F$6) -> 0 | G16: =COUNTIFS('RD Fine Kinney (Birim Bazlı)'!$D$8:$D$100,'Analiz (Birim Bazlı)'!$B16,'RD Fine Kinney (Birim Bazlı)'!$R$8:$R$100,'Analiz (Birim Bazlı)'!G$6) -> 0 | H16: =SUM(C16:G16) -> 0 | I16: =COUNTIFS('RD Fine Kinney (Birim Bazlı)'!$D$8:$D$100,'Analiz (Birim Bazlı)'!$B16,'RD Fine Kinney (Birim Bazlı)'!$AC$8:$AC$100,'Analiz (Birim Bazlı)'!I$6) -> 0 | J16: =COUNTIFS('RD Fine Kinney (Birim Bazlı)'!$D$8:$D$100,'Analiz (Birim Bazlı)'!$B16,'RD Fine Kinney (Birim Bazlı)'!$AC$8:$AC$100,'Analiz (Birim Bazlı)'!J$6) -> 0 | K16: =COUNTIFS('RD Fine Kinney (Birim Bazlı)'!$D$8:$D$100,'Analiz (Birim Bazlı)'!$B16,'RD Fine Kinney (Birim Bazlı)'!$AC$8:$AC$100,'Analiz (Birim Bazlı)'!K$6) -> 0 | L16: =COUNTIFS('RD Fine Kinney (Birim Bazlı)'!$D$8:$D$100,'Analiz (Birim Bazlı)'!$B16,'RD Fine Kinney (Birim Bazlı)'!$AC$8:$AC$100,'Analiz (Birim Bazlı)'!L$6) -> 0 | M16: =COUNTIFS('RD Fine Kinney (Birim Bazlı)'!$D$8:$D$100,'Analiz (Birim Bazlı)'!$B16,'RD Fine Kinney (Birim Bazlı)'!$AC$8:$AC$100,'Analiz (Birim Bazlı)'!M$6) -> 0 | N16: =SUM(I16:M16) -> 0
B17: Tehlikeli Madde Yönetimi / Kimyasal Risk Etmenleri | C17: =COUNTIFS('RD Fine Kinney (Birim Bazlı)'!$D$8:$D$100,'Analiz (Birim Bazlı)'!$B17,'RD Fine Kinney (Birim Bazlı)'!$R$8:$R$100,'Analiz (Birim Bazlı)'!C$6) -> 0 | D17: =COUNTIFS('RD Fine Kinney (Birim Bazlı)'!$D$8:$D$100,'Analiz (Birim Bazlı)'!$B17,'RD Fine Kinney (Birim Bazlı)'!$R$8:$R$100,'Analiz (Birim Bazlı)'!D$6) -> 0 | E17: =COUNTIFS('RD Fine Kinney (Birim Bazlı)'!$D$8:$D$100,'Analiz (Birim Bazlı)'!$B17,'RD Fine Kinney (Birim Bazlı)'!$R$8:$R$100,'Analiz (Birim Bazlı)'!E$6) -> 0 | F17: =COUNTIFS('RD Fine Kinney (Birim Bazlı)'!$D$8:$D$100,'Analiz (Birim Bazlı)'!$B17,'RD Fine Kinney (Birim Bazlı)'!$R$8:$R$100,'Analiz (Birim Bazlı)'!F$6) -> 0 | G17: =COUNTIFS('RD Fine Kinney (Birim Bazlı)'!$D$8:$D$100,'Analiz (Birim Bazlı)'!$B17,'RD Fine Kinney (Birim Bazlı)'!$R$8:$R$100,'Analiz (Birim Bazlı)'!G$6) -> 0 | H17: =SUM(C17:G17) -> 0 | I17: =COUNTIFS('RD Fine Kinney (Birim Bazlı)'!$D$8:$D$100,'Analiz (Birim Bazlı)'!$B17,'RD Fine Kinney (Birim Bazlı)'!$AC$8:$AC$100,'Analiz (Birim Bazlı)'!I$6) -> 0 | J17: =COUNTIFS('RD Fine Kinney (Birim Bazlı)'!$D$8:$D$100,'Analiz (Birim Bazlı)'!$B17,'RD Fine Kinney (Birim Bazlı)'!$AC$8:$AC$100,'Analiz (Birim Bazlı)'!J$6) -> 0 | K17: =COUNTIFS('RD Fine Kinney (Birim Bazlı)'!$D$8:$D$100,'Analiz (Birim Bazlı)'!$B17,'RD Fine Kinney (Birim Bazlı)'!$AC$8:$AC$100,'Analiz (Birim Bazlı)'!K$6) -> 0 | L17: =COUNTIFS('RD Fine Kinney (Birim Bazlı)'!$D$8:$D$100,'Analiz (Birim Bazlı)'!$B17,'RD Fine Kinney (Birim Bazlı)'!$AC$8:$AC$100,'Analiz (Birim Bazlı)'!L$6) -> 0 | M17: =COUNTIFS('RD Fine Kinney (Birim Bazlı)'!$D$8:$D$100,'Analiz (Birim Bazlı)'!$B17,'RD Fine Kinney (Birim Bazlı)'!$AC$8:$AC$100,'Analiz (Birim Bazlı)'!M$6) -> 0 | N17: =SUM(I17:M17) -> 0
B18: Tesis Güvenliği | C18: =COUNTIFS('RD Fine Kinney (Birim Bazlı)'!$C$8:$C$100,'Analiz (Birim Bazlı)'!$B18,'RD Fine Kinney (Birim Bazlı)'!$R$8:$R$100,'Analiz (Birim Bazlı)'!C$6) -> 0 | D18: =COUNTIFS('RD Fine Kinney (Birim Bazlı)'!$C$8:$C$100,'Analiz (Birim Bazlı)'!$B18,'RD Fine Kinney (Birim Bazlı)'!$R$8:$R$100,'Analiz (Birim Bazlı)'!D$6) -> 0 | E18: =COUNTIFS('RD Fine Kinney (Birim Bazlı)'!$C$8:$C$100,'Analiz (Birim Bazlı)'!$B18,'RD Fine Kinney (Birim Bazlı)'!$R$8:$R$100,'Analiz (Birim Bazlı)'!E$6) -> 0 | F18: =COUNTIFS('RD Fine Kinney (Birim Bazlı)'!$C$8:$C$100,'Analiz (Birim Bazlı)'!$B18,'RD Fine Kinney (Birim Bazlı)'!$R$8:$R$100,'Analiz (Birim Bazlı)'!F$6) -> 0 | G18: =COUNTIFS('RD Fine Kinney (Birim Bazlı)'!$C$8:$C$100,'Analiz (Birim Bazlı)'!$B18,'RD Fine Kinney (Birim Bazlı)'!$R$8:$R$100,'Analiz (Birim Bazlı)'!G$6) -> 0 | H18: =SUM(C18:G18) -> 0 | I18: =COUNTIFS('RD Fine Kinney (Birim Bazlı)'!$C$8:$C$100,'Analiz (Birim Bazlı)'!$B18,'RD Fine Kinney (Birim Bazlı)'!$AC$8:$AC$100,'Analiz (Birim Bazlı)'!I$6) -> 0 | J18: =COUNTIFS('RD Fine Kinney (Birim Bazlı)'!$C$8:$C$100,'Analiz (Birim Bazlı)'!$B18,'RD Fine Kinney (Birim Bazlı)'!$AC$8:$AC$100,'Analiz (Birim Bazlı)'!J$6) -> 0 | K18: =COUNTIFS('RD Fine Kinney (Birim Bazlı)'!$C$8:$C$100,'Analiz (Birim Bazlı)'!$B18,'RD Fine Kinney (Birim Bazlı)'!$AC$8:$AC$100,'Analiz (Birim Bazlı)'!K$6) -> 0 | L18: =COUNTIFS('RD Fine Kinney (Birim Bazlı)'!$C$8:$C$100,'Analiz (Birim Bazlı)'!$B18,'RD Fine Kinney (Birim Bazlı)'!$AC$8:$AC$100,'Analiz (Birim Bazlı)'!L$6) -> 0 | M18: =COUNTIFS('RD Fine Kinney (Birim Bazlı)'!$C$8:$C$100,'Analiz (Birim Bazlı)'!$B18,'RD Fine Kinney (Birim Bazlı)'!$AC$8:$AC$100,'Analiz (Birim Bazlı)'!M$6) -> 0 | N18: =SUM(I18:M18) -> 0
B19: Atık Yönetimi | C19: =COUNTIFS('RD Fine Kinney (Birim Bazlı)'!$D$8:$D$100,'Analiz (Birim Bazlı)'!$B19,'RD Fine Kinney (Birim Bazlı)'!$R$8:$R$100,'Analiz (Birim Bazlı)'!C$6) -> 0 | D19: =COUNTIFS('RD Fine Kinney (Birim Bazlı)'!$D$8:$D$100,'Analiz (Birim Bazlı)'!$B19,'RD Fine Kinney (Birim Bazlı)'!$R$8:$R$100,'Analiz (Birim Bazlı)'!D$6) -> 0 | E19: =COUNTIFS('RD Fine Kinney (Birim Bazlı)'!$D$8:$D$100,'Analiz (Birim Bazlı)'!$B19,'RD Fine Kinney (Birim Bazlı)'!$R$8:$R$100,'Analiz (Birim Bazlı)'!E$6) -> 0 | F19: =COUNTIFS('RD Fine Kinney (Birim Bazlı)'!$D$8:$D$100,'Analiz (Birim Bazlı)'!$B19,'RD Fine Kinney (Birim Bazlı)'!$R$8:$R$100,'Analiz (Birim Bazlı)'!F$6) -> 0 | G19: =COUNTIFS('RD Fine Kinney (Birim Bazlı)'!$D$8:$D$100,'Analiz (Birim Bazlı)'!$B19,'RD Fine Kinney (Birim Bazlı)'!$R$8:$R$100,'Analiz (Birim Bazlı)'!G$6) -> 0 | H19: =SUM(C19:G19) -> 0 | I19: =COUNTIFS('RD Fine Kinney (Birim Bazlı)'!$D$8:$D$100,'Analiz (Birim Bazlı)'!$B19,'RD Fine Kinney (Birim Bazlı)'!$AC$8:$AC$100,'Analiz (Birim Bazlı)'!I$6) -> 0 | J19: =COUNTIFS('RD Fine Kinney (Birim Bazlı)'!$D$8:$D$100,'Analiz (Birim Bazlı)'!$B19,'RD Fine Kinney (Birim Bazlı)'!$AC$8:$AC$100,'Analiz (Birim Bazlı)'!J$6) -> 0 | K19: =COUNTIFS('RD Fine Kinney (Birim Bazlı)'!$D$8:$D$100,'Analiz (Birim Bazlı)'!$B19,'RD Fine Kinney (Birim Bazlı)'!$AC$8:$AC$100,'Analiz (Birim Bazlı)'!K$6) -> 0 | L19: =COUNTIFS('RD Fine Kinney (Birim Bazlı)'!$D$8:$D$100,'Analiz (Birim Bazlı)'!$B19,'RD Fine Kinney (Birim Bazlı)'!$AC$8:$AC$100,'Analiz (Birim Bazlı)'!L$6) -> 0 | M19: =COUNTIFS('RD Fine Kinney (Birim Bazlı)'!$D$8:$D$100,'Analiz (Birim Bazlı)'!$B19,'RD Fine Kinney (Birim Bazlı)'!$AC$8:$AC$100,'Analiz (Birim Bazlı)'!M$6) -> 0 | N19: =SUM(I19:M19) -> 0
B20: Tıbbi Cihaz ve Malzeme Yönetimi | C20: =COUNTIFS('RD Fine Kinney (Birim Bazlı)'!$D$8:$D$100,'Analiz (Birim Bazlı)'!$B20,'RD Fine Kinney (Birim Bazlı)'!$R$8:$R$100,'Analiz (Birim Bazlı)'!C$6) -> 0 | D20: =COUNTIFS('RD Fine Kinney (Birim Bazlı)'!$D$8:$D$100,'Analiz (Birim Bazlı)'!$B20,'RD Fine Kinney (Birim Bazlı)'!$R$8:$R$100,'Analiz (Birim Bazlı)'!D$6) -> 0 | E20: =COUNTIFS('RD Fine Kinney (Birim Bazlı)'!$D$8:$D$100,'Analiz (Birim Bazlı)'!$B20,'RD Fine Kinney (Birim Bazlı)'!$R$8:$R$100,'Analiz (Birim Bazlı)'!E$6) -> 0 | F20: =COUNTIFS('RD Fine Kinney (Birim Bazlı)'!$D$8:$D$100,'Analiz (Birim Bazlı)'!$B20,'RD Fine Kinney (Birim Bazlı)'!$R$8:$R$100,'Analiz (Birim Bazlı)'!F$6) -> 0 | G20: =COUNTIFS('RD Fine Kinney (Birim Bazlı)'!$D$8:$D$100,'Analiz (Birim Bazlı)'!$B20,'RD Fine Kinney (Birim Bazlı)'!$R$8:$R$100,'Analiz (Birim Bazlı)'!G$6) -> 0 | H20: =SUM(C20:G20) -> 0 | I20: =COUNTIFS('RD Fine Kinney (Birim Bazlı)'!$D$8:$D$100,'Analiz (Birim Bazlı)'!$B20,'RD Fine Kinney (Birim Bazlı)'!$AC$8:$AC$100,'Analiz (Birim Bazlı)'!I$6) -> 0 | J20: =COUNTIFS('RD Fine Kinney (Birim Bazlı)'!$D$8:$D$100,'Analiz (Birim Bazlı)'!$B20,'RD Fine Kinney (Birim Bazlı)'!$AC$8:$AC$100,'Analiz (Birim Bazlı)'!J$6) -> 0 | K20: =COUNTIFS('RD Fine Kinney (Birim Bazlı)'!$D$8:$D$100,'Analiz (Birim Bazlı)'!$B20,'RD Fine Kinney (Birim Bazlı)'!$AC$8:$AC$100,'Analiz (Birim Bazlı)'!K$6) -> 0 | L20: =COUNTIFS('RD Fine Kinney (Birim Bazlı)'!$D$8:$D$100,'Analiz (Birim Bazlı)'!$B20,'RD Fine Kinney (Birim Bazlı)'!$AC$8:$AC$100,'Analiz (Birim Bazlı)'!L$6) -> 0 | M20: =COUNTIFS('RD Fine Kinney (Birim Bazlı)'!$D$8:$D$100,'Analiz (Birim Bazlı)'!$B20,'RD Fine Kinney (Birim Bazlı)'!$AC$8:$AC$100,'Analiz (Birim Bazlı)'!M$6) -> 0 | N20: =SUM(I20:M20) -> 0
B21: Diğer Cihaz ve Malzemelerin Yönetimi | C21: =COUNTIFS('RD Fine Kinney (Birim Bazlı)'!$D$8:$D$100,'Analiz (Birim Bazlı)'!$B21,'RD Fine Kinney (Birim Bazlı)'!$R$8:$R$100,'Analiz (Birim Bazlı)'!C$6) -> 0 | D21: =COUNTIFS('RD Fine Kinney (Birim Bazlı)'!$D$8:$D$100,'Analiz (Birim Bazlı)'!$B21,'RD Fine Kinney (Birim Bazlı)'!$R$8:$R$100,'Analiz (Birim Bazlı)'!D$6) -> 0 | E21: =COUNTIFS('RD Fine Kinney (Birim Bazlı)'!$D$8:$D$100,'Analiz (Birim Bazlı)'!$B21,'RD Fine Kinney (Birim Bazlı)'!$R$8:$R$100,'Analiz (Birim Bazlı)'!E$6) -> 0 | F21: =COUNTIFS('RD Fine Kinney (Birim Bazlı)'!$D$8:$D$100,'Analiz (Birim Bazlı)'!$B21,'RD Fine Kinney (Birim Bazlı)'!$R$8:$R$100,'Analiz (Birim Bazlı)'!F$6) -> 0 | G21: =COUNTIFS('RD Fine Kinney (Birim Bazlı)'!$D$8:$D$100,'Analiz (Birim Bazlı)'!$B21,'RD Fine Kinney (Birim Bazlı)'!$R$8:$R$100,'Analiz (Birim Bazlı)'!G$6) -> 0 | H21: =SUM(C21:G21) -> 0 | I21: =COUNTIFS('RD Fine Kinney (Birim Bazlı)'!$D$8:$D$100,'Analiz (Birim Bazlı)'!$B21,'RD Fine Kinney (Birim Bazlı)'!$AC$8:$AC$100,'Analiz (Birim Bazlı)'!I$6) -> 0 | J21: =COUNTIFS('RD Fine Kinney (Birim Bazlı)'!$D$8:$D$100,'Analiz (Birim Bazlı)'!$B21,'RD Fine Kinney (Birim Bazlı)'!$AC$8:$AC$100,'Analiz (Birim Bazlı)'!J$6) -> 0 | K21: =COUNTIFS('RD Fine Kinney (Birim Bazlı)'!$D$8:$D$100,'Analiz (Birim Bazlı)'!$B21,'RD Fine Kinney (Birim Bazlı)'!$AC$8:$AC$100,'Analiz (Birim Bazlı)'!K$6) -> 0 | L21: =COUNTIFS('RD Fine Kinney (Birim Bazlı)'!$D$8:$D$100,'Analiz (Birim Bazlı)'!$B21,'RD Fine Kinney (Birim Bazlı)'!$AC$8:$AC$100,'Analiz (Birim Bazlı)'!L$6) -> 0 | M21: =COUNTIFS('RD Fine Kinney (Birim Bazlı)'!$D$8:$D$100,'Analiz (Birim Bazlı)'!$B21,'RD Fine Kinney (Birim Bazlı)'!$AC$8:$AC$100,'Analiz (Birim Bazlı)'!M$6) -> 0 | N21: =SUM(I21:M21) -> 0
B22: Yangın Güvenliği | C22: =COUNTIFS('RD Fine Kinney (Birim Bazlı)'!$D$8:$D$100,'Analiz (Birim Bazlı)'!$B22,'RD Fine Kinney (Birim Bazlı)'!$R$8:$R$100,'Analiz (Birim Bazlı)'!C$6) -> 0 | D22: =COUNTIFS('RD Fine Kinney (Birim Bazlı)'!$D$8:$D$100,'Analiz (Birim Bazlı)'!$B22,'RD Fine Kinney (Birim Bazlı)'!$R$8:$R$100,'Analiz (Birim Bazlı)'!D$6) -> 0 | E22: =COUNTIFS('RD Fine Kinney (Birim Bazlı)'!$D$8:$D$100,'Analiz (Birim Bazlı)'!$B22,'RD Fine Kinney (Birim Bazlı)'!$R$8:$R$100,'Analiz (Birim Bazlı)'!E$6) -> 0 | F22: =COUNTIFS('RD Fine Kinney (Birim Bazlı)'!$D$8:$D$100,'Analiz (Birim Bazlı)'!$B22,'RD Fine Kinney (Birim Bazlı)'!$R$8:$R$100,'Analiz (Birim Bazlı)'!F$6) -> 0 | G22: =COUNTIFS('RD Fine Kinney (Birim Bazlı)'!$D$8:$D$100,'Analiz (Birim Bazlı)'!$B22,'RD Fine Kinney (Birim Bazlı)'!$R$8:$R$100,'Analiz (Birim Bazlı)'!G$6) -> 0 | H22: =SUM(C22:G22) -> 0 | I22: =COUNTIFS('RD Fine Kinney (Birim Bazlı)'!$D$8:$D$100,'Analiz (Birim Bazlı)'!$B22,'RD Fine Kinney (Birim Bazlı)'!$AC$8:$AC$100,'Analiz (Birim Bazlı)'!I$6) -> 0 | J22: =COUNTIFS('RD Fine Kinney (Birim Bazlı)'!$D$8:$D$100,'Analiz (Birim Bazlı)'!$B22,'RD Fine Kinney (Birim Bazlı)'!$AC$8:$AC$100,'Analiz (Birim Bazlı)'!J$6) -> 0 | K22: =COUNTIFS('RD Fine Kinney (Birim Bazlı)'!$D$8:$D$100,'Analiz (Birim Bazlı)'!$B22,'RD Fine Kinney (Birim Bazlı)'!$AC$8:$AC$100,'Analiz (Birim Bazlı)'!K$6) -> 0 | L22: =COUNTIFS('RD Fine Kinney (Birim Bazlı)'!$D$8:$D$100,'Analiz (Birim Bazlı)'!$B22,'RD Fine Kinney (Birim Bazlı)'!$AC$8:$AC$100,'Analiz (Birim Bazlı)'!L$6) -> 0 | M22: =COUNTIFS('RD Fine Kinney (Birim Bazlı)'!$D$8:$D$100,'Analiz (Birim Bazlı)'!$B22,'RD Fine Kinney (Birim Bazlı)'!$AC$8:$AC$100,'Analiz (Birim Bazlı)'!M$6) -> 0 | N22: =SUM(I22:M22) -> 0
B23: Altyapı Sistemleri | C23: =COUNTIFS('RD Fine Kinney (Birim Bazlı)'!$D$8:$D$100,'Analiz (Birim Bazlı)'!$B23,'RD Fine Kinney (Birim Bazlı)'!$R$8:$R$100,'Analiz (Birim Bazlı)'!C$6) -> 0 | D23: =COUNTIFS('RD Fine Kinney (Birim Bazlı)'!$D$8:$D$100,'Analiz (Birim Bazlı)'!$B23,'RD Fine Kinney (Birim Bazlı)'!$R$8:$R$100,'Analiz (Birim Bazlı)'!D$6) -> 0 | E23: =COUNTIFS('RD Fine Kinney (Birim Bazlı)'!$D$8:$D$100,'Analiz (Birim Bazlı)'!$B23,'RD Fine Kinney (Birim Bazlı)'!$R$8:$R$100,'Analiz (Birim Bazlı)'!E$6) -> 0 | F23: =COUNTIFS('RD Fine Kinney (Birim Bazlı)'!$D$8:$D$100,'Analiz (Birim Bazlı)'!$B23,'RD Fine Kinney (Birim Bazlı)'!$R$8:$R$100,'Analiz (Birim Bazlı)'!F$6) -> 0 | G23: =COUNTIFS('RD Fine Kinney (Birim Bazlı)'!$D$8:$D$100,'Analiz (Birim Bazlı)'!$B23,'RD Fine Kinney (Birim Bazlı)'!$R$8:$R$100,'Analiz (Birim Bazlı)'!G$6) -> 0 | H23: =SUM(C23:G23) -> 0 | I23: =COUNTIFS('RD Fine Kinney (Birim Bazlı)'!$D$8:$D$100,'Analiz (Birim Bazlı)'!$B23,'RD Fine Kinney (Birim Bazlı)'!$AC$8:$AC$100,'Analiz (Birim Bazlı)'!I$6) -> 0 | J23: =COUNTIFS('RD Fine Kinney (Birim Bazlı)'!$D$8:$D$100,'Analiz (Birim Bazlı)'!$B23,'RD Fine Kinney (Birim Bazlı)'!$AC$8:$AC$100,'Analiz (Birim Bazlı)'!J$6) -> 0 | K23: =COUNTIFS('RD Fine Kinney (Birim Bazlı)'!$D$8:$D$100,'Analiz (Birim Bazlı)'!$B23,'RD Fine Kinney (Birim Bazlı)'!$AC$8:$AC$100,'Analiz (Birim Bazlı)'!K$6) -> 0 | L23: =COUNTIFS('RD Fine Kinney (Birim Bazlı)'!$D$8:$D$100,'Analiz (Birim Bazlı)'!$B23,'RD Fine Kinney (Birim Bazlı)'!$AC$8:$AC$100,'Analiz (Birim Bazlı)'!L$6) -> 0 | M23: =COUNTIFS('RD Fine Kinney (Birim Bazlı)'!$D$8:$D$100,'Analiz (Birim Bazlı)'!$B23,'RD Fine Kinney (Birim Bazlı)'!$AC$8:$AC$100,'Analiz (Birim Bazlı)'!M$6) -> 0 | N23: =SUM(I23:M23) -> 0
